<?xml version="1.0" encoding="utf-8"?>
<!-- =================================================================================== -->
<!-- |    This document was autogenerated by xacro from ezrassor.xacro                 | -->
<!-- |    EDITING THIS FILE BY HAND IS NOT RECOMMENDED                                 | -->
<!-- =================================================================================== -->
<robot name="ezrassor">
  <gazebo reference="base_link">
    <selfCollide>0</selfCollide>
  </gazebo>
  <!-- Arms and Drums -->
  <gazebo reference="arm_front">
    <material>Gazebo/Black</material>
    <selfCollide>1</selfCollide>
  </gazebo>
  <gazebo reference="arm_back">
    <material>Gazebo/Black</material>
    <selfCollide>1</selfCollide>
  </gazebo>
  <gazebo reference="drum_front_hinge">
    <sensor name="force_torque" type="force_torque">
      <update_rate>1</update_rate>
    </sensor>
  </gazebo>
  <gazebo reference="drum_front">
    <selfCollide>1</selfCollide>
  </gazebo>
  <gazebo reference="drum_back">
    <selfCollide>1</selfCollide>
  </gazebo>
  <!-- Wheels -->
  <gazebo reference="left_wheel_front">
    <selfCollide>1</selfCollide>
    <mu1 value=".8"/>
    <mu2 value=".8"/>
    <kp value="10000000.0"/>
    <kd value="1.0"/>
    <fdir1 value="1 0 0"/>
  </gazebo>
  <gazebo reference="left_wheel_back">
    <selfCollide>1</selfCollide>
    <mu1 value=".8"/>
    <mu2 value=".8"/>
    <kp value="10000000.0"/>
    <kd value="1.0"/>
    <fdir1 value="1 0 0"/>
  </gazebo>
  <gazebo reference="right_wheel_front">
    <selfCollide>1</selfCollide>
    <mu1 value=".8"/>
    <mu2 value=".8"/>
    <kp value="10000000.0"/>
    <kd value="1.0"/>
    <fdir1 value="1 0 0"/>
  </gazebo>
  <gazebo reference="right_wheel_back">
    <selfCollide>1</selfCollide>
    <mu1 value=".8"/>
    <mu2 value=".8"/>
    <kp value="10000000.0"/>
    <kd value="1.0"/>
    <fdir1 value="1 0 0"/>
  </gazebo>
  <!-- Cameras -->
  <gazebo reference="depth_camera_front">
    <sensor name="depth_camera_front_camera" type="depth">
      <update_rate>30</update_rate>
      <camera>
        <horizontal_fov>1.29154</horizontal_fov>
        <image>
          <width>640</width>
          <height>480</height>
          <format>R8G8B8</format>
        </image>
        <clip>
          <near>0.105</near>
          <far>10</far>
        </clip>
      </camera>
      <plugin filename="libgazebo_ros_openni_kinect.so" name="depth_camera_front_controller">
        <baseline>0.2</baseline>
        <alwaysOn>true</alwaysOn>
        <updateRate>0.0</updateRate>
        <cameraName/>
        <imageTopicName>color/image_raw</imageTopicName>
        <cameraInfoTopicName>color/camera_info</cameraInfoTopicName>
        <depthImageTopicName>depth/image_raw</depthImageTopicName>
        <depthImageInfoTopicName>depth/camera_info</depthImageInfoTopicName>
        <pointCloudTopicName>depth/points</pointCloudTopicName>
        <frameName>/depth_camera_optical_frame</frameName>
        <pointCloudCutoff>0.105</pointCloudCutoff>
        <pointCloudCutoffMax>10</pointCloudCutoffMax>
        <distortionK1>0</distortionK1>
        <distortionK2>0</distortionK2>
        <distortionK3>0</distortionK3>
        <distortionT1>0</distortionT1>
        <distortionT2>0</distortionT2>
        <CxPrime>0</CxPrime>
        <Cx>0</Cx>
        <Cy>0</Cy>
        <focalLength>0</focalLength>
        <hackBaseline>0</hackBaseline>
      </plugin>
    </sensor>
  </gazebo>
  <!-- IMU -->
  <gazebo>
    <plugin filename="libgazebo_ros_imu.so" name="imu_plugin">
      <alwaysOn>true</alwaysOn>
      <updateRate>50.0</updateRate>
      <bodyName>imu_link</bodyName>
      <topicName>imu</topicName>
      <gaussianNoise>0.05</gaussianNoise>
    </plugin>
  </gazebo>
  <gazebo>
    <plugin filename="libgazebo_ros_control.so" name="gazebo_ros_control">
    </plugin>
  </gazebo>
  <material name="black">
    <color rgba="0.0 0.0 0.0 1.0"/>
  </material>
  <material name="blue">
    <color rgba="0.0 0.0 0.8 1.0"/>
  </material>
  <material name="green">
    <color rgba="0.0 0.8 0.0 1.0"/>
  </material>
  <material name="grey">
    <color rgba="0.2 0.2 0.2 1.0"/>
  </material>
  <material name="orange">
    <color rgba="1.0 0.423529411765 0.0392156862745 1.0"/>
  </material>
  <material name="brown">
    <color rgba="0.870588235294 0.811764705882 0.764705882353 1.0"/>
  </material>
  <material name="red">
    <color rgba="0.8 0.0 0.0 1.0"/>
  </material>
  <material name="white">
    <color rgba="1.0 1.0 1.0 1.0"/>
  </material>
  <!--Below are all of the robot's Links/-->
  <link name="base_link">
    <pose>0 0 0 0 0 0</pose>
  </link>
  <link name="body">
    <pose>0 0 0 0 0 0</pose>
    <inertial>
      <mass value="15.0"/>
      <origin rpy=" 0 0 0" xyz="0 0 0"/>
      <inertia ixx="0.5" ixy="0" ixz="0" iyy="1.0" iyz="0" izz="0.1"/>
    </inertial>
    <collision name="collision">
      <origin rpy=" 0 0 0" xyz="0 0 0"/>
      <geometry>
        <mesh filename="package://ezrassor_sim_description/meshes/base_unit.dae" scale="0.35 0.35 0.35"/>
      </geometry>
    </collision>
    <visual name="base_link_visual">
      <origin rpy=" 0 0 0" xyz="0 0 0"/>
      <geometry>
        <mesh filename="package://ezrassor_sim_description/meshes/base_unit.dae" scale="0.35 0.35 0.35"/>
      </geometry>
    </visual>
  </link>
  <link name="left_wheel_front">
    <collision name="collision">
      <origin rpy="0 0 0" xyz="0 0 0"/>
      <geometry>
        <mesh filename="package://ezrassor_sim_description/meshes/wheel.dae" scale="0.35 0.35 0.35"/>
      </geometry>
      <surface>
        <friction>
          <mu> .6 </mu>
          <mu2> .6 </mu2>
        </friction>
      </surface>
      <surface>
        <friction>
          <mu> .6 </mu>
          <mu2> .6 </mu2>
        </friction>
      </surface>
    </collision>
    <visual name="left_wheel_front_visual">
      <origin rpy="0 0 0" xyz="0 0 0"/>
      <geometry>
        <mesh filename="package://ezrassor_sim_description/meshes/wheel.dae" scale="0.35 0.35 0.35"/>
      </geometry>
    </visual>
    <inertial>
      <origin rpy="0 0 0" xyz="0 0 0"/>
      <mass value="5"/>
      <inertia ixx="0.0571666666667" ixy="0" ixz="0" iyy="0.0571666666667" iyz="0" izz="0.081"/>
    </inertial>
  </link>
  <link name="right_wheel_front">
    <collision name="collision">
      <origin rpy="0 0 3.14159" xyz="0 0 0"/>
      <geometry>
        <mesh filename="package://ezrassor_sim_description/meshes/wheel.dae" scale="0.35 0.35 0.35"/>
      </geometry>
      <surface>
        <friction>
          <mu> .6 </mu>
          <mu2> .6 </mu2>
        </friction>
      </surface>
    </collision>
    <visual name="right_wheel_front_visual">
      <origin rpy="0 0 3.14159" xyz="0 0 0"/>
      <geometry>
        <mesh filename="package://ezrassor_sim_description/meshes/wheel.dae" scale="0.35 0.35 0.35"/>
      </geometry>
    </visual>
    <inertial>
      <origin rpy="0 0 3.14159" xyz="0 0 0"/>
      <mass value="5"/>
      <inertia ixx="0.0571666666667" ixy="0" ixz="0" iyy="0.0571666666667" iyz="0" izz="0.081"/>
    </inertial>
  </link>
  <link name="left_wheel_back">
    <collision name="collision">
      <origin rpy="0 0 0" xyz="0 0 0"/>
      <geometry>
        <mesh filename="package://ezrassor_sim_description/meshes/wheel.dae" scale="0.35 0.35 0.35"/>
      </geometry>
      <surface>
        <friction>
          <mu> .6 </mu>
          <mu2> .6 </mu2>
        </friction>
      </surface>
    </collision>
    <visual name="left_wheel_back_visual">
      <origin rpy="0 0 0" xyz="0 0 0"/>
      <geometry>
        <mesh filename="package://ezrassor_sim_description/meshes/wheel.dae" scale="0.35 0.35 0.35"/>
      </geometry>
    </visual>
    <inertial>
      <origin rpy="0 0 0" xyz="0 0 0"/>
      <mass value="5"/>
      <inertia ixx="0.0571666666667" ixy="0" ixz="0" iyy="0.0571666666667" iyz="0" izz="0.081"/>
    </inertial>
  </link>
  <link name="right_wheel_back">
    <collision name="collision">
      <origin rpy="0 0 3.14159" xyz="0 0 0"/>
      <geometry>
        <mesh filename="package://ezrassor_sim_description/meshes/wheel.dae" scale="0.35 0.35 0.35"/>
      </geometry>
      <surface>
        <friction>
          <mu> .6 </mu>
          <mu2> .6 </mu2>
        </friction>
      </surface>
    </collision>
    <visual name="right_wheel_back_visual">
      <origin rpy="0 0 3.14159" xyz="0 0 0"/>
      <geometry>
        <mesh filename="package://ezrassor_sim_description/meshes/wheel.dae" scale="0.35 0.35 0.35"/>
      </geometry>
    </visual>
    <inertial>
      <origin rpy="0 0 3.14159" xyz="0 0 0"/>
      <mass value="5"/>
      <inertia ixx="0.0571666666667" ixy="0" ixz="0" iyy="0.0571666666667" iyz="0" izz="0.081"/>
    </inertial>
  </link>
  <link name="arm_front">
    <collision name="collision">
      <origin rpy="0 0 0" xyz="0 0 0"/>
      <geometry>
        <mesh filename="package://ezrassor_sim_description/meshes/drum_arm.dae" scale="0.35 0.35 0.35"/>
      </geometry>
    </collision>
    <visual name="visual">
      <origin rpy="0 0 0" xyz="0 0 0"/>
      <geometry>
        <mesh filename="package://ezrassor_sim_description/meshes/drum_arm.dae" scale="0.35 0.35 0.35"/>
      </geometry>
    </visual>
    <inertial>
      <origin rpy="0 0 0" xyz="0 0 0"/>
      <mass value="5"/>
      <inertia ixx="0.040625" ixy="0" ixz="0" iyy="0.040625" iyz="0" izz="0.00625"/>
    </inertial>
  </link>
  <link name="arm_back">
    <collision name="collision">
      <origin rpy="3.1415 0 3.1415" xyz="0 0 0"/>
      <geometry>
        <mesh filename="package://ezrassor_sim_description/meshes/drum_arm.dae" scale="0.35 0.35 0.35"/>
      </geometry>
    </collision>
    <visual name="visual">
      <origin rpy="3.1415 0 3.1415" xyz="0 0 0"/>
      <geometry>
        <mesh filename="package://ezrassor_sim_description/meshes/drum_arm.dae" scale="0.35 0.35 0.35"/>
      </geometry>
    </visual>
    <inertial>
      <origin rpy="0 0 3.1415" xyz="0 0 0"/>
      <mass value="5"/>
      <inertia ixx="0.040625" ixy="0" ixz="0" iyy="0.040625" iyz="0" izz="0.00625"/>
      <inertia ixx="1.0" ixy="0.0" ixz="0.0" iyy="1.0" iyz="0.0" izz="1.0"/>
    </inertial>
  </link>
  <link name="drum_front">
    <!-- <collision name="collision">
      <origin xyz="0 0 0" rpy="0 0 0"/>
      <geometry>
        <robot_arm_drum />
      </geometry>
    </collision>-->
    <collision name="collision">
      <origin rpy="0 1.5707 1.5707" xyz="0 0 0"/>
      <geometry>
        <cylinder length="1.0" radius="0.1839"/>
      </geometry>
    </collision>
    <visual name="drum_front_visual">
      <origin rpy="0 0 0" xyz="0 0 0"/>
      <geometry>
        <mesh filename="package://ezrassor_sim_description/meshes/drum.dae" scale="0.35 0.35 0.35"/>
      </geometry>
    </visual>
    <inertial>
      <origin rpy="0 0 0" xyz="0 0 0"/>
      <mass value="5"/>
      <inertia ixx="0.458940679167" ixy="0" ixz="0" iyy="0.458940679167" iyz="0" izz="0.084548025"/>
    </inertial>
  </link>
  <link name="drum_back">
    <!-- <collision name="collision">
      <origin xyz="0 0 0" rpy="0 0 3.14159"/>
      <geometry>
        <robot_arm_drum />
      </geometry>
    </collision> -->
    <collision name="collision">
      <origin rpy="0 1.5707 1.5707" xyz="0 0 0"/>
      <geometry>
        <cylinder length="1.0" radius="0.1839"/>
      </geometry>
    </collision>
    <visual name="drum_back">
      <origin rpy="3.1415 0 3.14159" xyz="0 0 0"/>
      <geometry>
        <mesh filename="package://ezrassor_sim_description/meshes/drum.dae" scale="0.35 0.35 0.35"/>
      </geometry>
    </visual>
    <inertial>
      <origin rpy="0 0 3.14159" xyz="0 0 0"/>
      <mass value="5"/>
      <inertia ixx="0.458940679167" ixy="0" ixz="0" iyy="0.458940679167" iyz="0" izz="0.084548025"/>
    </inertial>
  </link>
  <!-- Transmissions -->
  <transmission name="left_wheel_front_tran">
    <type>transmission_interface/SimpleTransmission</type>
    <joint name="left_wheel_front_hinge">
      <hardwareInterface>hardware_interface/VelocityJointInterface</hardwareInterface>
    </joint>
    <actuator name="left_wheel_front_motor">
      <hardwareInterface>hardware_interface/VelocityJointInterface</hardwareInterface>
      <mechanicalReduction>1</mechanicalReduction>
    </actuator>
  </transmission>
  <transmission name="left_wheel_back_tran">
    <type>transmission_interface/SimpleTransmission</type>
    <joint name="left_wheel_back_hinge">
      <hardwareInterface>hardware_interface/VelocityJointInterface</hardwareInterface>
    </joint>
    <actuator name="left_wheel_back_motor">
      <hardwareInterface>hardware_interface/VelocityJointInterface</hardwareInterface>
      <mechanicalReduction>1</mechanicalReduction>
    </actuator>
  </transmission>
  <transmission name="right_wheel_front_tran">
    <type>transmission_interface/SimpleTransmission</type>
    <joint name="right_wheel_front_hinge">
      <hardwareInterface>hardware_interface/VelocityJointInterface</hardwareInterface>
    </joint>
    <actuator name="right_wheel_front_motor">
      <hardwareInterface>hardware_interface/VelocityJointInterface</hardwareInterface>
      <mechanicalReduction>1</mechanicalReduction>
    </actuator>
  </transmission>
  <transmission name="right_wheel_back_tran">
    <type>transmission_interface/SimpleTransmission</type>
    <joint name="right_wheel_back_hinge">
      <hardwareInterface>hardware_interface/VelocityJointInterface</hardwareInterface>
    </joint>
    <actuator name="right_wheel_back_motor">
      <hardwareInterface>hardware_interface/VelocityJointInterface</hardwareInterface>
      <mechanicalReduction>1</mechanicalReduction>
    </actuator>
  </transmission>
  <transmission name="arm_front_tran">
    <type>transmission_interface/SimpleTransmission</type>
    <joint name="arm_front_hinge">
      <hardwareInterface>hardware_interface/VelocityJointInterface</hardwareInterface>
    </joint>
    <actuator name="arm_front_motor">
      <hardwareInterface>hardware_interface/VelocityJointInterface</hardwareInterface>
      <mechanicalReduction>1</mechanicalReduction>
    </actuator>
  </transmission>
  <transmission name="arm_back_tran">
    <type>transmission_interface/SimpleTransmission</type>
    <joint name="arm_back_hinge">
      <hardwareInterface>hardware_interface/VelocityJointInterface</hardwareInterface>
    </joint>
    <actuator name="arm_back_motor">
      <hardwareInterface>hardware_interface/VelocityJointInterface</hardwareInterface>
      <mechanicalReduction>1</mechanicalReduction>
    </actuator>
  </transmission>
  <transmission name="drum_front_hinge_tran">
    <type>transmission_interface/SimpleTransmission</type>
    <joint name="drum_front_hinge">
      <hardwareInterface>hardware_interface/VelocityJointInterface</hardwareInterface>
    </joint>
    <actuator name="drum_front_hinge_motor">
      <hardwareInterface>hardware_interface/VelocityJointInterface</hardwareInterface>
      <mechanicalReduction>1</mechanicalReduction>
    </actuator>
  </transmission>
  <transmission name="drum_back_hinge_tran">
    <type>transmission_interface/SimpleTransmission</type>
    <joint name="drum_back_hinge">
      <hardwareInterface>hardware_interface/VelocityJointInterface</hardwareInterface>
    </joint>
    <actuator name="drum_back_hinge_motor">
      <hardwareInterface>hardware_interface/VelocityJointInterface</hardwareInterface>
      <mechanicalReduction>1</mechanicalReduction>
    </actuator>
  </transmission>
  <!-- Front Camera Added -->
  <link name="depth_camera_front">
    <collision>
      <origin rpy="0 0 0" xyz="0 0 0"/>
      <geometry>
        <box size="0.01 0.01 0.01"/>
      </geometry>
    </collision>
    <visual>
      <origin rpy="0 0 0" xyz="0 0 0"/>
      <geometry>
        <box size="0.01 0.01 0.01"/>
      </geometry>
      <material name="green"/>
    </visual>
    <inertial>
      <mass value="0.1"/>
      <origin rpy="0 0 0" xyz="0 0 0"/>
      <inertia ixx="1.66666666667e-06" ixy="0" ixz="0" iyy="1.66666666667e-06" iyz="0" izz="1.66666666667e-06"/>
      <inertia ixx="1e-6" ixy="0" ixz="0" iyy="1e-6" iyz="0" izz="1e-6"/>
    </inertial>
  </link>
  <link name="imu_link">
    <collision>
      <origin rpy="0 0 0" xyz="0 0 0"/>
      <geometry>
        <box size="0.01 0.01 0.01"/>
      </geometry>
    </collision>
    <visual>
      <origin rpy="0 0 0" xyz="0 0 0"/>
      <geometry>
        <box size="0.01 0.01 0.01"/>
      </geometry>
      <material name="green"/>
    </visual>
    <inertial>
      <mass value="0.1"/>
      <origin rpy="0 0 0" xyz="0 0 0"/>
      <inertia ixx="1.66666666667e-06" ixy="0" ixz="0" iyy="1.66666666667e-06" iyz="0" izz="1.66666666667e-06"/>
      <inertia ixx="1e-6" ixy="0" ixz="0" iyy="1e-6" iyz="0" izz="1e-6"/>
    </inertial>
  </link>
  <joint name="body_joint" type="fixed">
    <axis xyz="0 0 0"/>
    <origin rpy="0 0 0" xyz="0 0 0"/>
    <parent link="base_link"/>
    <child link="body"/>
  </joint>
  <joint name="imu_joint" type="fixed">
    <axis xyz="0 0 0"/>
    <origin rpy="0 0 0" xyz="0 0 0"/>
    <parent link="base_link"/>
    <child link="imu_link"/>
  </joint>
  <joint name="camera_front_joint" type="fixed">
    <origin rpy="0 0 0" xyz=".3 0 -.1"/>
    <axis xyz="0 1 0"/>
    <parent link="base_link"/>
    <child link="depth_camera_front"/>
  </joint>
  <joint name="depth_camera_optical_joint" type="fixed">
    <origin rpy="-1.57079632679 0 -1.57079632679" xyz="0 0 0"/>
    <parent link="depth_camera_front"/>
    <child link="depth_camera_optical_frame"/>
  </joint>
  <link name="depth_camera_optical_frame"/>
  <joint name="left_wheel_front_hinge" type="continuous">
    <origin rpy="0 0 0" xyz="0.20 0.285 0"/>
    <child link="left_wheel_front"/>
    <parent link="base_link"/>
    <axis rpy="0 0 0" xyz="0 1 0"/>
    <limit effort="100" velocity="100"/>
    <joint_properties damping="0.0" friction="0.0"/>
  </joint>
  <joint name="right_wheel_front_hinge" type="continuous">
    <origin rpy="0 0 0" xyz="0.20 -0.285 0"/>
    <child link="right_wheel_front"/>
    <parent link="base_link"/>
    <axis rpy="0 0 0" xyz="0 1 0"/>
    <limit effort="100" velocity="100"/>
    <joint_properties damping="0.0" friction="0.0"/>
  </joint>
  <joint name="left_wheel_back_hinge" type="continuous">
    <origin rpy="0 0 0" xyz="-0.20 0.285 0"/>
    <child link="left_wheel_back"/>
    <parent link="base_link"/>
    <axis rpy="0 0 0" xyz="0 1 0"/>
    <limit effort="100" velocity="100"/>
    <joint_properties damping="0.0" friction="0.0"/>
  </joint>
  <joint name="right_wheel_back_hinge" type="continuous">
    <origin rpy="0 0 0" xyz="-0.20 -0.285 0"/>
    <child link="right_wheel_back"/>
    <parent link="base_link"/>
    <axis rpy="0 0 0" xyz="0 1 0"/>
    <limit effort="100" velocity="100"/>
    <joint_properties damping="0.0" friction="0.0"/>
  </joint>
  <joint name="arm_front_hinge" type="continuous">
    <origin rpy="3.1415 0 0" xyz="0.20 0 0"/>
    <child link="arm_front"/>
    <parent link="base_link"/>
    <axis rpy="0 0 0" xyz="0 1 0"/>
    <limit effort="100" velocity="100"/>
    <joint_properties damping="0.0" friction="0.0"/>
  </joint>
  <joint name="arm_back_hinge" type="continuous">
    <origin rpy="0 0 0" xyz="-0.20 0 0"/>
    <child link="arm_back"/>
    <parent link="base_link"/>
    <axis rpy="0 0 0" xyz="0 1 0"/>
    <limit effort="100" velocity="100"/>
    <joint_properties damping="0.0" friction="0.0"/>
  </joint>
  <joint name="drum_front_hinge" type="continuous">
    <origin rpy="3.1415 0 0" xyz="0.388245 0 0"/>
    <child link="drum_front"/>
    <parent link="arm_front"/>
    <axis rpy="0 0 0" xyz="0 1 0"/>
    <limit effort="100" velocity="100"/>
    <joint_properties damping="0.0" friction="0.0"/>
  </joint>
  <joint name="drum_back_hinge" type="continuous">
    <origin rpy="3.1415 0 0" xyz="-0.388245 0 0"/>
    <child link="drum_back"/>
    <parent link="arm_back"/>
    <axis rpy="0 0 0" xyz="0 1 0"/>
    <limit effort="100" velocity="100"/>
    <joint_properties damping="0.0" friction="0.0"/>
  </joint>
</robot>

