<sdf version='1.6'>
  <world name='moon'>
    <scene>
      <background>0 0 0 255</background>
      <ambient>0.4 0.4 0.4 1</ambient>
      <shadows>1</shadows>
    </scene>
    <light name='sun' type='directional'>
      <cast_shadows>1</cast_shadows>
      <pose frame=''>0 0 10 0 -0 0</pose>
      <diffuse>0.8 0.8 0.8 1</diffuse>
      <specular>0.1 0.1 0.1 1</specular>
      <attenuation>
        <range>1000</range>
        <constant>0.9</constant>
        <linear>0.01</linear>
        <quadratic>0.001</quadratic>
      </attenuation>
      <direction>-0.5 0.5 -1</direction>
    </light>
    <model name='apollo15_landing_site_1000x1000'>
      <static>1</static>
      <link name='link'>
        <collision name='collision'>
          <surface>
            <friction>
              <ode>
                <mu>30</mu>
              </ode>
              <torsional>
                <ode/>
              </torsional>
            </friction>
            <contact>
              <ode>
                <soft_cfm>1</soft_cfm>
                <kp>100000</kp>
                <kd>1</kd>
                <max_vel>1e-06</max_vel>
                <min_depth>0.02</min_depth>
              </ode>
            </contact>
            <bounce/>
          </surface>
          <geometry>
            <heightmap>
              <uri>model://apollo15_landing_site_1000x1000/materials/textures/NAC_DTM_APOLLO15_E261N0036_257x257+7472+2152.png</uri>
              <size>514 514 49</size>
              <pos>0 0 -45</pos>
              <texture>
                <size>10</size>
                <diffuse>__default__</diffuse>
                <normal>__default__</normal>
              </texture>
              <blend>
                <min_height>0</min_height>
                <fade_dist>0</fade_dist>
              </blend>
            </heightmap>
          </geometry>
          <max_contacts>10</max_contacts>
        </collision>
        <visual name='visual'>
          <geometry>
            <heightmap>
              <texture>
                <diffuse>model://apollo15_landing_site_1000x1000/materials/textures/AS16-110-18026HR-512x512.jpg</diffuse>
                <normal>file://media/materials/textures/flat_normal.png</normal>
                <size>2</size>
              </texture>
              <uri>model://apollo15_landing_site_1000x1000/materials/textures/NAC_DTM_APOLLO15_E261N0036_257x257+7472+2152.png</uri>
              <size>514 514 49</size>
              <pos>0 0 -45</pos>
              <blend>
                <min_height>0</min_height>
                <fade_dist>0</fade_dist>
              </blend>
            </heightmap>
          </geometry>
        </visual>
        <self_collide>0</self_collide>
        <kinematic>0</kinematic>
        <gravity>1</gravity>
      </link>
    </model>
    <light name='sun' type='directional'>
      <cast_shadows>1</cast_shadows>
      <pose frame=''>0 0 10 0 -0 0</pose>
      <diffuse>0.8 0.8 0.8 1</diffuse>
      <specular>0.1 0.1 0.1 1</specular>
      <attenuation>
        <range>1000</range>
        <constant>0.9</constant>
        <linear>0.01</linear>
        <quadratic>0.001</quadratic>
      </attenuation>
      <direction>-0.5 0.5 -1</direction>
    </light>
    <physics name='default_physics' default='0' type='ode'>
      <max_step_size>0.01</max_step_size>
      <real_time_factor>1</real_time_factor>
      <real_time_update_rate>100</real_time_update_rate>
    </physics>
    <gravity>0 0 -1.622</gravity>
    <magnetic_field>6e-06 2.3e-05 -4.2e-05</magnetic_field>
    <atmosphere type='adiabatic'/>
    <spherical_coordinates>
      <surface_model>EARTH_WGS84</surface_model>
      <latitude_deg>0</latitude_deg>
      <longitude_deg>0</longitude_deg>
      <elevation>0</elevation>
      <heading_deg>0</heading_deg>
    </spherical_coordinates>
    <model name='gazebo'>
      <static>1</static>
      <link name='link'>
        <collision name='collision'>
          <geometry>
            <mesh>
              <scale>1 1 1</scale>
              <uri>model://gazebo/meshes/gazebo.dae</uri>
            </mesh>
          </geometry>
          <max_contacts>10</max_contacts>
          <surface>
            <contact>
              <ode/>
            </contact>
            <bounce/>
            <friction>
              <torsional>
                <ode/>
              </torsional>
              <ode/>
            </friction>
          </surface>
        </collision>
        <visual name='visual'>
          <geometry>
            <mesh>
              <scale>1 1 1</scale>
              <uri>model://gazebo/meshes/gazebo.dae</uri>
            </mesh>
          </geometry>
        </visual>
        <self_collide>0</self_collide>
        <kinematic>0</kinematic>
        <gravity>1</gravity>
      </link>
      <pose frame=''>-3.03475 4.4135 0 0 -0 0</pose>
    </model>
    <state world_name='moon'>
      <sim_time>400 160000000</sim_time>
      <real_time>311 661025296</real_time>
      <wall_time>1554701956 216832245</wall_time>
      <iterations>30978</iterations>
      <model name='apollo15_landing_site_1000x1000'>
        <pose frame=''>0 0 0 0 -0 0</pose>
        <scale>1 1 1</scale>
        <link name='link'>
          <pose frame=''>0 0 0 0 -0 0</pose>
          <velocity>0 0 0 0 -0 0</velocity>
          <acceleration>0 0 0 0 -0 0</acceleration>
          <wrench>0 0 0 0 -0 0</wrench>
        </link>
      </model>
      <model name='ezrassor'>
        <pose frame=''>1.30427 -13.31 1.03842 1.57019 0.000493 0.002506</pose>
        <scale>1 1 1</scale>
        <link name='arm_back'>
          <pose frame=''>1.10427 -13.3105 1.03841 1.57004 0.009314 0.124621</pose>
          <velocity>-0.000217 0.000231 -0.007505 -0.001201 0.005952 0.00034</velocity>
          <acceleration>0 1e-06 0 -7e-06 1.5e-05 -5e-06</acceleration>
          <wrench>-1e-06 3e-06 -2e-06 0 -0 0</wrench>
        </link>
        <link name='arm_front'>
          <pose frame=''>1.50427 -13.3095 1.03841 1.57019 -0.009266 -0.038335</pose>
          <velocity>0.00012 0.000342 -0.007771 -0.001222 -0.004692 0.000139</velocity>
          <acceleration>0 1e-06 -1e-06 -4e-06 -7e-06 8e-06</acceleration>
          <wrench>-1e-06 3e-06 -3e-06 0 -0 0</wrench>
        </link>
        <link name='base_link'>
          <pose frame=''>1.30427 -13.31 1.03842 1.57019 0.000493 0.002506</pose>
          <velocity>-8e-05 0.000283 -0.007272 -0.001151 -4.6e-05 0.000246</velocity>
          <acceleration>0 1e-06 -1e-06 1e-06 1.5e-05 0</acceleration>
          <wrench>-3e-06 9e-06 -8e-06 0 -0 0</wrench>
        </link>
        <link name='drum_back'>
          <pose frame=''>0.719007 -13.3588 1.04224 1.56621 0.009112 -0.270901</pose>
          <velocity>-0.000794 -5.5e-05 -0.037209 0.000685 -0.002131 -0.000512</velocity>
          <acceleration>-1e-06 3e-06 -2e-06 -8e-06 -7e-06 -4e-06</acceleration>
          <wrench>-3e-06 1.5e-05 -1.2e-05 0 -0 0</wrench>
        </link>
        <link name='drum_front'>
          <pose frame=''>1.89225 -13.3244 1.04218 1.56934 -0.009924 0.047295</pose>
          <velocity>0.000634 0.000488 -0.037515 -0.000811 0.001527 0.000322</velocity>
          <acceleration>0 4e-06 -2e-06 -7e-06 -0 -1e-06</acceleration>
          <wrench>0 1.8e-05 -8e-06 0 -0 0</wrench>
        </link>
        <link name='left_wheel_back'>
          <pose frame=''>1.10444 -13.3103 1.3235 1.57018 0.000454 -0.032936</pose>
          <velocity>-0.000237 0.000586 -0.007143 -0.001254 0.000107 0.000247</velocity>
          <acceleration>0 0 0 1e-06 -0 0</acceleration>
          <wrench>0 2e-06 -2e-06 0 -0 0</wrench>
        </link>
        <link name='left_wheel_front'>
          <pose frame=''>1.50441 -13.3093 1.32329 1.57029 0.000673 0.156048</pose>
          <velocity>-8.1e-05 0.00068 -0.007067 -0.00124 -0.000582 0.000243</velocity>
          <acceleration>0 0 -1e-06 1e-06 -0 0</acceleration>
          <wrench>0 2e-06 -3e-06 0 -0 0</wrench>
        </link>
        <link name='right_wheel_back'>
          <pose frame=''>1.1041 -13.3107 0.75351 1.57003 -0.000166 -0.904595</pose>
          <velocity>0.000121 -0.000118 -0.007219 -0.001221 -5.3e-05 0.000247</velocity>
          <acceleration>0 1e-06 0 0 -0 0</acceleration>
          <wrench>-2e-06 4e-06 -2e-06 0 -0 0</wrench>
        </link>
        <link name='right_wheel_front'>
          <pose frame=''>1.50413 -13.3097 0.753294 1.5701 0.000487 -0.174482</pose>
          <velocity>-6.3e-05 -9e-06 -0.007092 -0.001194 -0.000708 0.000248</velocity>
          <acceleration>0 1e-06 -1e-06 1e-06 -0 0</acceleration>
          <wrench>-2e-06 4e-06 -3e-06 0 -0 0</wrench>
        </link>
      </model>
      <model name='gazebo'>
        <pose frame=''>-0.001402 0.006713 0 0 -0 0</pose>
        <scale>1 1 1</scale>
        <link name='link'>
          <pose frame=''>-0.001402 0.006713 0 0 -0 0</pose>
          <velocity>0 0 0 0 -0 0</velocity>
          <acceleration>0 0 0 0 -0 0</acceleration>
          <wrench>0 0 0 0 -0 0</wrench>
        </link>
      </model>
      <model name='number1'>
        <pose frame=''>7.59024 2.79297 1.06018 0 -0 0</pose>
        <scale>1 1 1</scale>
        <link name='link'>
          <pose frame=''>7.59024 2.79297 1.06018 0 -0 0</pose>
          <velocity>0 0 0 0 -0 0</velocity>
          <acceleration>0 0 0 0 -0 0</acceleration>
          <wrench>0 0 0 0 -0 0</wrench>
        </link>
      </model>
      <model name='number1_clone'>
        <pose frame=''>17.0592 18.9666 0.897276 0 -0 0</pose>
        <scale>1 1 1</scale>
        <link name='link'>
          <pose frame=''>17.0592 18.9666 0.897276 0 -0 0</pose>
          <velocity>0 0 0 0 -0 0</velocity>
          <acceleration>0 0 0 0 -0 0</acceleration>
          <wrench>0 0 0 0 -0 0</wrench>
        </link>
      </model>
      <model name='number1_clone_0'>
        <pose frame=''>14.8234 9.40475 1.06018 0 -0 0</pose>
        <scale>1 1 1</scale>
        <link name='link'>
          <pose frame=''>14.8234 9.40475 1.06018 0 -0 0</pose>
          <velocity>0 0 0 0 -0 0</velocity>
          <acceleration>0 0 0 0 -0 0</acceleration>
          <wrench>0 0 0 0 -0 0</wrench>
        </link>
      </model>
      <model name='number1_clone_1'>
        <pose frame=''>15.4361 -1.6518 1.06018 0 -0 0</pose>
        <scale>1 1 1</scale>
        <link name='link'>
          <pose frame=''>15.4361 -1.6518 1.06018 0 -0 0</pose>
          <velocity>0 0 0 0 -0 0</velocity>
          <acceleration>0 0 0 0 -0 0</acceleration>
          <wrench>0 0 0 0 -0 0</wrench>
        </link>
      </model>
      <model name='number1_clone_2'>
        <pose frame=''>10.864 -10.16 1.06018 0 -0 0</pose>
        <scale>1 1 1</scale>
        <link name='link'>
          <pose frame=''>10.864 -10.16 1.06018 0 -0 0</pose>
          <velocity>0 0 0 0 -0 0</velocity>
          <acceleration>0 0 0 0 -0 0</acceleration>
          <wrench>0 0 0 0 -0 0</wrench>
        </link>
      </model>
      <model name='number1_clone_3'>
        <pose frame=''>8.4913 18.4744 0.332375 0 -0 0</pose>
        <scale>1 1 1</scale>
        <link name='link'>
          <pose frame=''>8.4913 18.4744 0.332375 0 -0 0</pose>
          <velocity>0 0 0 0 -0 0</velocity>
          <acceleration>0 0 0 0 -0 0</acceleration>
          <wrench>0 0 0 0 -0 0</wrench>
        </link>
      </model>
      <light name='sun'>
        <pose frame=''>0 0 10 0 -0 0</pose>
      </light>
    </state>
    <gui fullscreen='0'>
      <camera name='user_camera'>
        <pose frame=''>16.3249 -27.6364 14.6277 -0 0.621796 2.22418</pose>
        <view_controller>orbit</view_controller>
        <projection_type>perspective</projection_type>
      </camera>
    </gui>
    <model name='ezrassor'>
      <link name='base_link'>
        <pose frame=''>0 0 0 0 -0 0</pose>
        <inertial>
          <pose frame=''>0.001974 0 -0.000658 0 -0 0</pose>
          <mass>15.2</mass>
          <inertia>
            <ixx>0.501047</ixx>
            <ixy>0</ixy>
            <ixz>0.00298026</ixz>
            <iyy>1.00999</iyy>
            <iyz>0</iyz>
            <izz>0.108994</izz>
          </inertia>
        </inertial>
        <collision name='base_link_fixed_joint_lump__collision_collision'>
          <pose frame=''>0 0 0 0 -0 0</pose>
          <geometry>
            <mesh>
              <scale>1 1 1</scale>
              <uri>/home/cameron/.workspace/src/ezrassor_sim_description/meshes/base_unit.dae</uri>
            </mesh>
          </geometry>
          <max_contacts>10</max_contacts>
          <surface>
            <contact>
              <ode/>
            </contact>
            <bounce/>
            <friction>
              <torsional>
                <ode/>
              </torsional>
              <ode/>
            </friction>
          </surface>
        </collision>
        <collision name='base_link_fixed_joint_lump__stereo_camera_front_collision_1'>
          <pose frame=''>0.3 0 -0.1 0 -0 0</pose>
          <geometry>
            <box>
              <size>0.04 0.04 0.04</size>
            </box>
          </geometry>
          <surface>
            <contact>
              <ode/>
            </contact>
            <friction>
              <ode/>
              <torsional>
                <ode/>
              </torsional>
            </friction>
            <bounce/>
          </surface>
          <max_contacts>10</max_contacts>
        </collision>
        <collision name='base_link_fixed_joint_lump__imu_link_collision_2'>
          <pose frame=''>0 0 0 0 -0 0</pose>
          <geometry>
            <box>
              <size>0.04 0.04 0.04</size>
            </box>
          </geometry>
          <surface>
            <contact>
              <ode/>
            </contact>
            <friction>
              <ode/>
              <torsional>
                <ode/>
              </torsional>
            </friction>
            <bounce/>
          </surface>
          <max_contacts>10</max_contacts>
        </collision>
        <visual name='base_link_visual_visual'>
          <pose frame=''>0 0 0 0 -0 0</pose>
          <geometry>
            <mesh>
              <scale>1 1 1</scale>
              <uri>/home/cameron/.workspace/src/ezrassor_sim_description/meshes/base_unit.dae</uri>
            </mesh>
          </geometry>
          <material>
            <script>
              <uri>__default__</uri>
              <name>__default__</name>
            </script>
          </material>
        </visual>
        <visual name='base_link_fixed_joint_lump__stereo_camera_front_visual_1'>
          <pose frame=''>0.3 0 -0.1 0 -0 0</pose>
          <geometry>
            <box>
              <size>0.04 0.04 0.04</size>
            </box>
          </geometry>
          <material>
            <script>
              <uri>__default__</uri>
              <name>__default__</name>
            </script>
          </material>
        </visual>
        <visual name='base_link_fixed_joint_lump__imu_link_visual_2'>
          <pose frame=''>0 0 0 0 -0 0</pose>
          <geometry>
            <box>
              <size>0.04 0.04 0.04</size>
            </box>
          </geometry>
          <material>
            <script>
              <uri>__default__</uri>
              <name>__default__</name>
            </script>
          </material>
        </visual>
        <velocity_decay/>
        <velocity_decay/>
        <sensor name='stereo_camera' type='multicamera'>
          <update_rate>60</update_rate>
          <camera name='left'>
            <pose frame=''>0 0.035 0 0 -0 0</pose>
            <horizontal_fov>1.39626</horizontal_fov>
            <image>
              <width>640</width>
              <height>480</height>
              <format>R8G8B8</format>
            </image>
            <clip>
              <near>0.02</near>
              <far>300</far>
            </clip>
            <noise>
              <type>gaussian</type>
              <mean>0</mean>
              <stddev>0.007</stddev>
            </noise>
          </camera>
          <camera name='right'>
            <pose frame=''>0 -0.035 0 0 -0 0</pose>
            <horizontal_fov>1.39626</horizontal_fov>
            <image>
              <width>640</width>
              <height>480</height>
              <format>R8G8B8</format>
            </image>
            <clip>
              <near>0.02</near>
              <far>300</far>
            </clip>
            <noise>
              <type>gaussian</type>
              <mean>0</mean>
              <stddev>0.007</stddev>
            </noise>
          </camera>
          <plugin name='stereo_camera_controller' filename='libgazebo_ros_multicamera.so'>
            <focalLength>0</focalLength>
            <alwaysOn>true</alwaysOn>
            <updateRate>0.0</updateRate>
            <cameraName>ezrassor/front_camera</cameraName>
            <imageTopicName>image_raw</imageTopicName>
            <cameraInfoTopicName>camera_info</cameraInfoTopicName>
            <frameName>left_camera_optical_frame</frameName>
            <rightFrameName>right_camera_optical_frame</rightFrameName>
            <hackBaseline>0.07</hackBaseline>
            <distortionK1>0.0</distortionK1>
            <distortionK2>0.0</distortionK2>
            <distortionK3>0.0</distortionK3>
            <distortionT1>0.0</distortionT1>
            <distortionT2>0.0</distortionT2>
            <robotNamespace>/</robotNamespace>
          </plugin>
          <pose frame=''>0.3 0 -0.1 0 -0 0</pose>
        </sensor>
        <gravity>1</gravity>
        <velocity_decay/>
        <self_collide>0</self_collide>
        <gravity>1</gravity>
        <sensor name='imu_sensor' type='imu'>
          <always_on>1</always_on>
          <update_rate>100</update_rate>
          <visualize>1</visualize>
          <topic>__default_topic__</topic>
          <plugin name='imu_plugin' filename='libgazebo_ros_imu_sensor.so'>
            <topicName>imu</topicName>
            <bodyName>imu_link</bodyName>
            <updateRateHZ>10.0</updateRateHZ>
            <gaussianNoise>0.0</gaussianNoise>
            <xyzOffset>0 0 0</xyzOffset>
            <rpyOffset>0 0 0</rpyOffset>
            <frameName>imu_link</frameName>
            <robotNamespace>/</robotNamespace>
          </plugin>
          <pose frame=''>0 0 0 0 -0 0</pose>
        </sensor>
        <kinematic>0</kinematic>
      </link>
      <link name='arm_back'>
        <pose frame=''>-0.2 0 0 0 -0 0</pose>
        <inertial>
          <pose frame=''>0 0 0 0 -0 3.1415</pose>
          <mass>5</mass>
          <inertia>
            <ixx>0.040625</ixx>
            <ixy>0</ixy>
            <ixz>0</ixz>
            <iyy>0.040625</iyy>
            <iyz>0</iyz>
            <izz>0.00625</izz>
          </inertia>
        </inertial>
        <collision name='arm_back_fixed_joint_lump__collision_collision'>
          <pose frame=''>0 0 0 0 -0 3.1415</pose>
          <geometry>
            <mesh>
              <scale>1 1 1</scale>
              <uri>/home/cameron/.workspace/src/ezrassor_sim_description/meshes/drum_arm.dae</uri>
            </mesh>
          </geometry>
          <max_contacts>10</max_contacts>
          <surface>
            <contact>
              <ode/>
            </contact>
            <bounce/>
            <friction>
              <torsional>
                <ode/>
              </torsional>
              <ode/>
            </friction>
          </surface>
        </collision>
        <visual name='arm_back_fixed_joint_lump__visual_visual'>
          <pose frame=''>0 0 0 0 -0 3.1415</pose>
          <geometry>
            <mesh>
              <scale>1 1 1</scale>
              <uri>/home/cameron/.workspace/src/ezrassor_sim_description/meshes/drum_arm.dae</uri>
            </mesh>
          </geometry>
        </visual>
        <gravity>1</gravity>
        <velocity_decay/>
        <self_collide>1</self_collide>
        <kinematic>0</kinematic>
      </link>
      <joint name='arm_back_hinge' type='revolute'>
        <child>arm_back</child>
        <parent>base_link</parent>
        <axis>
          <xyz>0 1 0</xyz>
          <limit>
            <lower>-1e+16</lower>
            <upper>1e+16</upper>
          </limit>
          <dynamics>
            <spring_reference>0</spring_reference>
            <spring_stiffness>0</spring_stiffness>
          </dynamics>
          <use_parent_model_frame>1</use_parent_model_frame>
        </axis>
      </joint>
      <link name='drum_back'>
        <pose frame=''>-0.588245 0 0 0 -0 0</pose>
        <inertial>
          <pose frame=''>0 0 0 0 -0 3.14159</pose>
          <mass>5</mass>
          <inertia>
            <ixx>0.458941</ixx>
            <ixy>0</ixy>
            <ixz>0</ixz>
            <iyy>0.458941</iyy>
            <iyz>0</iyz>
            <izz>0.084548</izz>
          </inertia>
        </inertial>
        <collision name='drum_back_fixed_joint_lump__collision_collision'>
          <pose frame=''>0 0 0 3.14159 1.57079 -1.57089</pose>
          <geometry>
            <cylinder>
              <length>1</length>
              <radius>0.1839</radius>
            </cylinder>
          </geometry>
          <max_contacts>10</max_contacts>
          <surface>
            <contact>
              <ode/>
            </contact>
            <bounce/>
            <friction>
              <torsional>
                <ode/>
              </torsional>
              <ode/>
            </friction>
          </surface>
        </collision>
        <visual name='drum_back_visual'>
          <pose frame=''>0 0 0 0 -0 3.14159</pose>
          <geometry>
            <mesh>
              <scale>1 1 1</scale>
              <uri>/home/cameron/.workspace/src/ezrassor_sim_description/meshes/drum.dae</uri>
            </mesh>
          </geometry>
          <material>
            <script>
              <uri>__default__</uri>
              <name>__default__</name>
            </script>
          </material>
        </visual>
        <gravity>1</gravity>
        <velocity_decay/>
        <self_collide>1</self_collide>
        <kinematic>0</kinematic>
      </link>
      <joint name='drum_back_hinge' type='revolute'>
        <child>drum_back</child>
        <parent>arm_back</parent>
        <axis>
          <xyz>0 1 0</xyz>
          <limit>
            <lower>-1e+16</lower>
            <upper>1e+16</upper>
          </limit>
          <dynamics>
            <spring_reference>0</spring_reference>
            <spring_stiffness>0</spring_stiffness>
          </dynamics>
          <use_parent_model_frame>1</use_parent_model_frame>
        </axis>
      </joint>
      <link name='arm_front'>
        <pose frame=''>0.2 0 0 0 -0 0</pose>
        <inertial>
          <pose frame=''>0 0 0 0 -0 0</pose>
          <mass>5</mass>
          <inertia>
            <ixx>0.040625</ixx>
            <ixy>0</ixy>
            <ixz>0</ixz>
            <iyy>0.040625</iyy>
            <iyz>0</iyz>
            <izz>0.00625</izz>
          </inertia>
        </inertial>
        <collision name='arm_front_fixed_joint_lump__collision_collision'>
          <pose frame=''>0 0 0 0 -0 0</pose>
          <geometry>
            <mesh>
              <scale>1 1 1</scale>
              <uri>/home/cameron/.workspace/src/ezrassor_sim_description/meshes/drum_arm.dae</uri>
            </mesh>
          </geometry>
          <max_contacts>10</max_contacts>
          <surface>
            <contact>
              <ode/>
            </contact>
            <bounce/>
            <friction>
              <torsional>
                <ode/>
              </torsional>
              <ode/>
            </friction>
          </surface>
        </collision>
        <visual name='arm_front_fixed_joint_lump__visual_visual'>
          <pose frame=''>0 0 0 0 -0 0</pose>
          <geometry>
            <mesh>
              <scale>1 1 1</scale>
              <uri>/home/cameron/.workspace/src/ezrassor_sim_description/meshes/drum_arm.dae</uri>
            </mesh>
          </geometry>
        </visual>
        <gravity>1</gravity>
        <velocity_decay/>
        <self_collide>1</self_collide>
        <kinematic>0</kinematic>
      </link>
      <joint name='arm_front_hinge' type='revolute'>
        <child>arm_front</child>
        <parent>base_link</parent>
        <axis>
          <xyz>0 1 0</xyz>
          <limit>
            <lower>-1e+16</lower>
            <upper>1e+16</upper>
          </limit>
          <dynamics>
            <spring_reference>0</spring_reference>
            <spring_stiffness>0</spring_stiffness>
          </dynamics>
          <use_parent_model_frame>1</use_parent_model_frame>
        </axis>
      </joint>
      <link name='drum_front'>
        <pose frame=''>0.588245 0 0 0 -0 0</pose>
        <inertial>
          <pose frame=''>0 0 0 0 -0 0</pose>
          <mass>5</mass>
          <inertia>
            <ixx>0.458941</ixx>
            <ixy>0</ixy>
            <ixz>0</ixz>
            <iyy>0.458941</iyy>
            <iyz>0</iyz>
            <izz>0.084548</izz>
          </inertia>
        </inertial>
        <collision name='drum_front_fixed_joint_lump__collision_collision'>
          <pose frame=''>0 0 0 3.14159 1.57079 -1.57089</pose>
          <geometry>
            <cylinder>
              <length>1</length>
              <radius>0.1839</radius>
            </cylinder>
          </geometry>
          <max_contacts>10</max_contacts>
          <surface>
            <contact>
              <ode/>
            </contact>
            <bounce/>
            <friction>
              <torsional>
                <ode/>
              </torsional>
              <ode/>
            </friction>
          </surface>
        </collision>
        <visual name='drum_front_visual_visual'>
          <pose frame=''>0 0 0 0 -0 0</pose>
          <geometry>
            <mesh>
              <scale>1 1 1</scale>
              <uri>/home/cameron/.workspace/src/ezrassor_sim_description/meshes/drum.dae</uri>
            </mesh>
          </geometry>
          <material>
            <script>
              <uri>__default__</uri>
              <name>__default__</name>
            </script>
          </material>
        </visual>
        <gravity>1</gravity>
        <velocity_decay/>
        <self_collide>1</self_collide>
        <kinematic>0</kinematic>
      </link>
      <joint name='drum_front_hinge' type='revolute'>
        <child>drum_front</child>
        <parent>arm_front</parent>
        <axis>
          <xyz>0 1 0</xyz>
          <limit>
            <lower>-1e+16</lower>
            <upper>1e+16</upper>
          </limit>
          <dynamics>
            <spring_reference>0</spring_reference>
            <spring_stiffness>0</spring_stiffness>
          </dynamics>
          <use_parent_model_frame>1</use_parent_model_frame>
        </axis>
        <physics>
          <ode>
            <limit>
              <cfm>0</cfm>
              <erp>0.2</erp>
            </limit>
          </ode>
        </physics>
        <sensor name='force_torque' type='force_torque'>
          <update_rate>1</update_rate>
        </sensor>
      </joint>
      <link name='left_wheel_back'>
        <pose frame=''>-0.2 0.285 0 0 -0 0</pose>
        <inertial>
          <pose frame=''>0 0 0 0 -0 0</pose>
          <mass>5</mass>
          <inertia>
            <ixx>0.0571667</ixx>
            <ixy>0</ixy>
            <ixz>0</ixz>
            <iyy>0.0571667</iyy>
            <iyz>0</iyz>
            <izz>0.081</izz>
          </inertia>
        </inertial>
        <collision name='left_wheel_back_fixed_joint_lump__collision_collision'>
          <pose frame=''>0 0 0 0 -0 0</pose>
          <geometry>
            <mesh>
              <scale>1 1 1</scale>
              <uri>/home/cameron/.workspace/src/ezrassor_sim_description/meshes/wheel.dae</uri>
            </mesh>
          </geometry>
          <max_contacts>10</max_contacts>
          <surface>
            <contact>
              <ode/>
            </contact>
            <bounce/>
            <friction>
              <torsional>
                <ode/>
              </torsional>
              <ode/>
            </friction>
          </surface>
        </collision>
        <visual name='left_wheel_back_visual_visual'>
          <pose frame=''>0 0 0 0 -0 0</pose>
          <geometry>
            <mesh>
              <scale>1 1 1</scale>
              <uri>/home/cameron/.workspace/src/ezrassor_sim_description/meshes/wheel.dae</uri>
            </mesh>
          </geometry>
          <material>
            <script>
              <uri>__default__</uri>
              <name>__default__</name>
            </script>
          </material>
        </visual>
        <gravity>1</gravity>
        <velocity_decay/>
        <self_collide>1</self_collide>
        <kinematic>0</kinematic>
      </link>
      <joint name='left_wheel_back_hinge' type='revolute'>
        <child>left_wheel_back</child>
        <parent>base_link</parent>
        <axis>
          <xyz>0 1 0</xyz>
          <limit>
            <lower>-1e+16</lower>
            <upper>1e+16</upper>
          </limit>
          <dynamics>
            <spring_reference>0</spring_reference>
            <spring_stiffness>0</spring_stiffness>
          </dynamics>
          <use_parent_model_frame>1</use_parent_model_frame>
        </axis>
      </joint>
      <link name='left_wheel_front'>
        <pose frame=''>0.2 0.285 0 0 -0 0</pose>
        <inertial>
          <pose frame=''>0 0 0 0 -0 0</pose>
          <mass>5</mass>
          <inertia>
            <ixx>0.0571667</ixx>
            <ixy>0</ixy>
            <ixz>0</ixz>
            <iyy>0.0571667</iyy>
            <iyz>0</iyz>
            <izz>0.081</izz>
          </inertia>
        </inertial>
        <collision name='left_wheel_front_fixed_joint_lump__collision_collision'>
          <pose frame=''>0 0 0 0 -0 0</pose>
          <geometry>
            <mesh>
              <scale>1 1 1</scale>
              <uri>/home/cameron/.workspace/src/ezrassor_sim_description/meshes/wheel.dae</uri>
            </mesh>
          </geometry>
          <max_contacts>10</max_contacts>
          <surface>
            <contact>
              <ode/>
            </contact>
            <bounce/>
            <friction>
              <torsional>
                <ode/>
              </torsional>
              <ode/>
            </friction>
          </surface>
        </collision>
        <visual name='left_wheel_front_visual_visual'>
          <pose frame=''>0 0 0 0 -0 0</pose>
          <geometry>
            <mesh>
              <scale>1 1 1</scale>
              <uri>/home/cameron/.workspace/src/ezrassor_sim_description/meshes/wheel.dae</uri>
            </mesh>
          </geometry>
          <material>
            <script>
              <uri>__default__</uri>
              <name>__default__</name>
            </script>
          </material>
        </visual>
        <gravity>1</gravity>
        <velocity_decay/>
        <self_collide>1</self_collide>
        <kinematic>0</kinematic>
      </link>
      <joint name='left_wheel_front_hinge' type='revolute'>
        <child>left_wheel_front</child>
        <parent>base_link</parent>
        <axis>
          <xyz>0 1 0</xyz>
          <limit>
            <lower>-1e+16</lower>
            <upper>1e+16</upper>
          </limit>
          <dynamics>
            <spring_reference>0</spring_reference>
            <spring_stiffness>0</spring_stiffness>
          </dynamics>
          <use_parent_model_frame>1</use_parent_model_frame>
        </axis>
      </joint>
      <link name='right_wheel_back'>
        <pose frame=''>-0.2 -0.285 0 0 -0 0</pose>
        <inertial>
          <pose frame=''>0 0 0 0 -0 3.14159</pose>
          <mass>5</mass>
          <inertia>
            <ixx>0.0571667</ixx>
            <ixy>0</ixy>
            <ixz>0</ixz>
            <iyy>0.0571667</iyy>
            <iyz>0</iyz>
            <izz>0.081</izz>
          </inertia>
        </inertial>
        <collision name='right_wheel_back_fixed_joint_lump__collision_collision'>
          <pose frame=''>0 0 0 0 -0 3.14159</pose>
          <geometry>
            <mesh>
              <scale>1 1 1</scale>
              <uri>/home/cameron/.workspace/src/ezrassor_sim_description/meshes/wheel.dae</uri>
            </mesh>
          </geometry>
          <max_contacts>10</max_contacts>
          <surface>
            <contact>
              <ode/>
            </contact>
            <bounce/>
            <friction>
              <torsional>
                <ode/>
              </torsional>
              <ode/>
            </friction>
          </surface>
        </collision>
        <visual name='right_wheel_back_visual_visual'>
          <pose frame=''>0 0 0 0 -0 3.14159</pose>
          <geometry>
            <mesh>
              <scale>1 1 1</scale>
              <uri>/home/cameron/.workspace/src/ezrassor_sim_description/meshes/wheel.dae</uri>
            </mesh>
          </geometry>
          <material>
            <script>
              <uri>__default__</uri>
              <name>__default__</name>
            </script>
          </material>
        </visual>
        <gravity>1</gravity>
        <velocity_decay/>
        <self_collide>1</self_collide>
        <kinematic>0</kinematic>
      </link>
      <joint name='right_wheel_back_hinge' type='revolute'>
        <child>right_wheel_back</child>
        <parent>base_link</parent>
        <axis>
          <xyz>0 1 0</xyz>
          <limit>
            <lower>-1e+16</lower>
            <upper>1e+16</upper>
          </limit>
          <dynamics>
            <spring_reference>0</spring_reference>
            <spring_stiffness>0</spring_stiffness>
          </dynamics>
          <use_parent_model_frame>1</use_parent_model_frame>
        </axis>
      </joint>
      <link name='right_wheel_front'>
        <pose frame=''>0.2 -0.285 0 0 -0 0</pose>
        <inertial>
          <pose frame=''>0 0 0 0 -0 3.14159</pose>
          <mass>5</mass>
          <inertia>
            <ixx>0.0571667</ixx>
            <ixy>0</ixy>
            <ixz>0</ixz>
            <iyy>0.0571667</iyy>
            <iyz>0</iyz>
            <izz>0.081</izz>
          </inertia>
        </inertial>
        <collision name='right_wheel_front_fixed_joint_lump__collision_collision'>
          <pose frame=''>0 0 0 0 -0 3.14159</pose>
          <geometry>
            <mesh>
              <scale>1 1 1</scale>
              <uri>/home/cameron/.workspace/src/ezrassor_sim_description/meshes/wheel.dae</uri>
            </mesh>
          </geometry>
          <max_contacts>10</max_contacts>
          <surface>
            <contact>
              <ode/>
            </contact>
            <bounce/>
            <friction>
              <torsional>
                <ode/>
              </torsional>
              <ode/>
            </friction>
          </surface>
        </collision>
        <visual name='right_wheel_front_visual_visual'>
          <pose frame=''>0 0 0 0 -0 3.14159</pose>
          <geometry>
            <mesh>
              <scale>1 1 1</scale>
              <uri>/home/cameron/.workspace/src/ezrassor_sim_description/meshes/wheel.dae</uri>
            </mesh>
          </geometry>
          <material>
            <script>
              <uri>__default__</uri>
              <name>__default__</name>
            </script>
          </material>
        </visual>
        <gravity>1</gravity>
        <velocity_decay/>
        <self_collide>1</self_collide>
        <kinematic>0</kinematic>
      </link>
      <joint name='right_wheel_front_hinge' type='revolute'>
        <child>right_wheel_front</child>
        <parent>base_link</parent>
        <axis>
          <xyz>0 1 0</xyz>
          <limit>
            <lower>-1e+16</lower>
            <upper>1e+16</upper>
          </limit>
          <dynamics>
            <spring_reference>0</spring_reference>
            <spring_stiffness>0</spring_stiffness>
          </dynamics>
          <use_parent_model_frame>1</use_parent_model_frame>
        </axis>
      </joint>
      <static>0</static>
      <plugin name='gazebo_ros_control' filename='libgazebo_ros_control.so'>
        <robotNamespace>/ezrassor</robotNamespace>
      </plugin>
      <pose frame=''>3 -4 0.2 0 -0 0</pose>
    </model>
    <model name='number1'>
      <pose frame=''>2.70296 8.72327 0.4 0 -0 0</pose>
      <static>1</static>
      <link name='link'>
        <visual name='visual'>
          <geometry>
            <mesh>
              <uri>model://number1/meshes/number.dae</uri>
              <scale>1 1 1</scale>
            </mesh>
          </geometry>
          <material>
            <script>
              <uri>model://number1/materials/scripts</uri>
              <uri>model://number1/materials/textures</uri>
              <name>Number/One</name>
            </script>
          </material>
        </visual>
        <self_collide>0</self_collide>
        <kinematic>0</kinematic>
        <gravity>1</gravity>
      </link>
    </model>
    <model name='number1_clone_0'>
      <pose frame=''>14.8234 9.40475 1.06018 0 -0 0</pose>
      <static>1</static>
      <link name='link'>
        <visual name='visual'>
          <geometry>
            <mesh>
              <uri>model://number1/meshes/number.dae</uri>
              <scale>1 1 1</scale>
            </mesh>
          </geometry>
          <material>
            <script>
              <uri>model://number1/materials/scripts</uri>
              <uri>model://number1/materials/textures</uri>
              <name>Number/One</name>
            </script>
          </material>
        </visual>
        <self_collide>0</self_collide>
        <kinematic>0</kinematic>
        <gravity>1</gravity>
      </link>
    </model>
    <model name='number1_clone_1'>
      <pose frame=''>15.4361 -1.6518 1.06018 0 -0 0</pose>
      <static>1</static>
      <link name='link'>
        <visual name='visual'>
          <geometry>
            <mesh>
              <uri>model://number1/meshes/number.dae</uri>
              <scale>1 1 1</scale>
            </mesh>
          </geometry>
          <material>
            <script>
              <uri>model://number1/materials/scripts</uri>
              <uri>model://number1/materials/textures</uri>
              <name>Number/One</name>
            </script>
          </material>
        </visual>
        <self_collide>0</self_collide>
        <kinematic>0</kinematic>
        <gravity>1</gravity>
      </link>
    </model>
    <model name='number1_clone_2'>
      <pose frame=''>10.864 -10.16 1.06018 0 -0 0</pose>
      <static>1</static>
      <link name='link'>
        <visual name='visual'>
          <geometry>
            <mesh>
              <uri>model://number1/meshes/number.dae</uri>
              <scale>1 1 1</scale>
            </mesh>
          </geometry>
          <material>
            <script>
              <uri>model://number1/materials/scripts</uri>
              <uri>model://number1/materials/textures</uri>
              <name>Number/One</name>
            </script>
          </material>
        </visual>
        <self_collide>0</self_collide>
        <kinematic>0</kinematic>
        <gravity>1</gravity>
      </link>
    </model>
    <model name='number1_clone_3'>
      <pose frame=''>8.4913 18.4744 1.06018 0 -0 0</pose>
      <static>1</static>
      <link name='link'>
        <visual name='visual'>
          <geometry>
            <mesh>
              <uri>model://number1/meshes/number.dae</uri>
              <scale>1 1 1</scale>
            </mesh>
          </geometry>
          <material>
            <script>
              <uri>model://number1/materials/scripts</uri>
              <uri>model://number1/materials/textures</uri>
              <name>Number/One</name>
            </script>
          </material>
        </visual>
        <self_collide>0</self_collide>
        <kinematic>0</kinematic>
        <gravity>1</gravity>
      </link>
    </model>
    <model name='number1_clone'>
      <pose frame=''>17.0592 18.9666 1.06018 0 -0 0</pose>
      <static>1</static>
      <link name='link'>
        <visual name='visual'>
          <geometry>
            <mesh>
              <uri>model://number1/meshes/number.dae</uri>
              <scale>1 1 1</scale>
            </mesh>
          </geometry>
          <material>
            <script>
              <uri>model://number1/materials/scripts</uri>
              <uri>model://number1/materials/textures</uri>
              <name>Number/One</name>
            </script>
          </material>
        </visual>
        <self_collide>0</self_collide>
        <kinematic>0</kinematic>
        <gravity>1</gravity>
      </link>
    </model>
  </world>
</sdf>
