<?xml version="1.0" ?>
<robot name="ez_rassor">
  <joint name="left_wheel_back_hinge" type="revolute">
    <parent link="base_link"/>
    <child link="left_wheel_back"/>
    <origin rpy="0  0  0" xyz="-0.15  0.15  0"/>
    <axis xyz="0  1  0"/>
    <limit effort="-1.0" lower="-1e+16" upper="1e+16" velocity="-1.0"/>
  </joint>
  <joint name="left_wheel_front_hinge" type="revolute">
    <parent link="base_link"/>
    <child link="left_wheel_front"/>
    <origin rpy="0  0  0" xyz="0.15  0.15  0"/>
    <axis xyz="0  1  0"/>
    <limit effort="-1.0" lower="-1e+16" upper="1e+16" velocity="-1.0"/>
  </joint>
  <joint name="right_wheel_back_hinge" type="revolute">
    <parent link="base_link"/>
    <child link="right_wheel_back"/>
    <origin rpy="0  0  0" xyz="-0.15 -0.15  0"/>
    <axis xyz="0  1  0"/>
    <limit effort="-1.0" lower="-1e+16" upper="1e+16" velocity="-1.0"/>
  </joint>
  <joint name="right_wheel_front_hinge" type="revolute">
    <parent link="base_link"/>
    <child link="right_wheel_front"/>
    <origin rpy="0  0  0" xyz="0.15 -0.15  0"/>
    <axis xyz="0  1  0"/>
    <limit effort="-1.0" lower="-1e+16" upper="1e+16" velocity="-1.0"/>
  </joint>
  <link name="base_link">
    <inertial>
      <mass value="22"/>
      <origin rpy="0  0  0" xyz="0       0       0.00454"/>
      <inertia ixx="1" ixy="0" ixz="0" iyy="1" iyz="0" izz="1"/>
    </inertial>
    <collision name="ez_rassor_base_link_fixed_joint_lump__collision_collision_1">
      <origin rpy="3.14159000e+00   1.57079000e+00  -8.90000000e-04" xyz="-3.00000000e-01   8.00000000e-05   0.00000000e+00"/>
      <geometry>
        <cylinder length="0.3" radius="0.025"/>
      </geometry>
    </collision>
    <collision name="ez_rassor_base_link_fixed_joint_lump__camera_back_collision_3">
      <origin rpy="3.14159  1.57079  1.56841" xyz="-5.00000000e-01   3.10000000e-04   0.00000000e+00"/>
      <geometry>
        <box size="0.1 0.1 0.1"/>
      </geometry>
    </collision>
    <collision name="ez_rassor_base_link_fixed_joint_lump__collision_collision">
      <origin rpy="0  0  0" xyz="0  0  0"/>
      <geometry>
        <box size="0.4 0.2 0.1"/>
      </geometry>
    </collision>
    <collision name="ez_rassor_base_link_fixed_joint_lump__collision_collision_2">
      <origin rpy="-3.14159  1.57079  1.56911" xyz="-4.00000000e-01   1.50000000e-04   0.00000000e+00"/>
      <geometry>
        <cylinder length="0.05" radius="0.07"/>
      </geometry>
    </collision>
    <collision name="ez_rassor_base_link_fixed_joint_lump__collision_collision_4">
      <origin rpy="3.14159000e+00   1.57079000e+00  -8.90000000e-04" xyz="3.00000000e-01  -8.00000000e-05   0.00000000e+00"/>
      <geometry>
        <cylinder length="0.3" radius="0.025"/>
      </geometry>
    </collision>
    <collision name="ez_rassor_base_link_fixed_joint_lump__collision_collision_5">
      <origin rpy="-3.14159  1.57079  1.56911" xyz="4.00000000e-01  -1.50000000e-04   0.00000000e+00"/>
      <geometry>
        <cylinder length="0.05" radius="0.07"/>
      </geometry>
    </collision>
    <visual name="ez_rassor_base_link_fixed_joint_lump__arm_back_visual_visual_1">
      <origin rpy="-3.14157000e+00   1.57079000e+00  -8.60000000e-04" xyz="-3.00000000e-01   8.00000000e-05   0.00000000e+00"/>
      <geometry>
        <cylinder length="0.3" radius="0.025"/>
      </geometry>
    </visual>
    <visual name="ez_rassor_base_link_visual_visual">
      <origin rpy="0  0  0" xyz="0  0  0"/>
      <geometry>
        <box size="0.4 0.2 0.1"/>
      </geometry>
    </visual>
    <visual name="ez_rassor_base_link_fixed_joint_lump__arm_front_visual_visual_4">
      <origin rpy="-3.14157000e+00   1.57079000e+00  -8.60000000e-04" xyz="3.00000000e-01  -8.00000000e-05   0.00000000e+00"/>
      <geometry>
        <cylinder length="0.3" radius="0.025"/>
      </geometry>
    </visual>
    <visual name="ez_rassor_base_link_fixed_joint_lump__drum_back_visual_2">
      <origin rpy="-3.14075  1.57079  1.56995" xyz="-4.00000000e-01   1.50000000e-04   0.00000000e+00"/>
      <geometry>
        <cylinder length="0.4" radius="0.08"/>
      </geometry>
    </visual>
    <visual name="ez_rassor_base_link_fixed_joint_lump__camera_back_visual_3">
      <origin rpy="0    0    3.14" xyz="-5.00000000e-01   3.10000000e-04   0.00000000e+00"/>
      <geometry>
        <box size="0.1 0.1 0.1"/>
      </geometry>
    </visual>
    <visual name="ez_rassor_base_link_fixed_joint_lump__drum_front_visual_visual_5">
      <origin rpy="-3.14075  1.57079  1.56995" xyz="4.00000000e-01  -1.50000000e-04   0.00000000e+00"/>
      <geometry>
        <cylinder length="0.4" radius="0.08"/>
      </geometry>
    </visual>
  </link>
  <link name="left_wheel_back">
    <inertial>
      <mass value="0.5"/>
      <origin rpy="0      1.5707  1.5707" xyz="0  0  0"/>
      <inertia ixx="0.00135417" ixy="0" ixz="0" iyy="0.00135417" iyz="0" izz="0.0025"/>
    </inertial>
    <collision name="ez_rassor_left_wheel_back_fixed_joint_lump__collision_collision">
      <origin rpy="3.14159  1.57079 -1.57089" xyz="0   -0.06  0"/>
      <geometry>
        <mesh filename="package://ez_rassor_description/meshes/wheel.dae" scale="1.0 1.0 1.0"/>
      </geometry>
    </collision>
    <visual name="ez_rassor_left_wheel_back_visual_visual">
      <origin rpy="-3.12268  1.57079 -1.55198" xyz="0   -0.06  0"/>
      <geometry>
        <mesh filename="package://ez_rassor_description/meshes/wheel.dae" scale="1 1 1"/>
      </geometry>
    </visual>
  </link>
  <link name="left_wheel_front">
    <inertial>
      <mass value="0.5"/>
      <origin rpy="0      1.5707  1.5707" xyz="0  0  0"/>
      <inertia ixx="0.00135417" ixy="0" ixz="0" iyy="0.00135417" iyz="0" izz="0.0025"/>
    </inertial>
    <collision name="ez_rassor_left_wheel_front_fixed_joint_lump__collision_collision">
      <origin rpy="3.14159  1.57079 -1.57089" xyz="0   -0.06  0"/>
      <geometry>
        <mesh filename="package://ez_rassor_description/meshes/wheel.dae" scale="1.0 1.0 1.0"/>
      </geometry>
    </collision>
    <visual name="ez_rassor_left_wheel_front_visual_visual">
      <origin rpy="-3.12268  1.57079 -1.55198" xyz="0   -0.06  0"/>
      <geometry>
        <mesh filename="package://ez_rassor_description/meshes/wheel.dae" scale="1 1 1"/>
      </geometry>
    </visual>
  </link>
  <link name="right_wheel_back">
    <inertial>
      <mass value="0.5"/>
      <origin rpy="0      1.5707  1.5707" xyz="0  0  0"/>
      <inertia ixx="0.00135417" ixy="0" ixz="0" iyy="0.00135417" iyz="0" izz="0.0025"/>
    </inertial>
    <collision name="ez_rassor_right_wheel_back_fixed_joint_lump__collision_collision">
      <origin rpy="0       1.57079 -1.57089" xyz="0    0.06  0"/>
      <geometry>
        <mesh filename="package://ez_rassor_description/meshes/wheel.dae" scale="1.0 1.0 1.0"/>
      </geometry>
    </collision>
    <visual name="ez_rassor_right_wheel_back_visual_visual">
      <origin rpy="-0.00702  1.57079 -1.57316" xyz="0    0.06  0"/>
      <geometry>
        <mesh filename="package://ez_rassor_description/meshes/wheel.dae" scale="1 1 1"/>
      </geometry>
    </visual>
  </link>
  <link name="right_wheel_front">
    <inertial>
      <mass value="0.5"/>
      <origin rpy="0      1.5707  1.5707" xyz="0  0  0"/>
      <inertia ixx="0.00135417" ixy="0" ixz="0" iyy="0.00135417" iyz="0" izz="0.0025"/>
    </inertial>
    <collision name="ez_rassor_right_wheel_front_fixed_joint_lump__collision_collision">
      <origin rpy="0       1.57079 -1.57089" xyz="0    0.06  0"/>
      <geometry>
        <mesh filename="package://ez_rassor_description/meshes/wheel.dae" scale="1.0 1.0 1.0"/>
      </geometry>
    </collision>
    <visual name="ez_rassor_right_wheel_front_visual_visual">
      <origin rpy="-0.00702  1.57079 -1.57316" xyz="0    0.06  0"/>
      <geometry>
        <mesh filename="package://ez_rassor_description/meshes/wheel.dae" scale="1 1 1"/>
      </geometry>
    </visual>
  </link>
</robot>
