<?xml version='1.0'?>
<sdf version='1.6'>
  <model name='ez_rassor'>
    <link name='base_link'>
      <pose frame=''>0 0 0 0 -0 0</pose>
      <inertial>
        <pose frame=''>0 0 0.004545 0 -0 0</pose>
        <mass>22</mass>
        <inertia>
          <ixx>1</ixx>
          <ixy>0</ixy>
          <ixz>0</ixz>
          <iyy>1</iyy>
          <iyz>0</iyz>
          <izz>1</izz>
        </inertia>
      </inertial>
      <self_collide>0</self_collide>
      <kinematic>0</kinematic>
      <velocity_decay/>
      <sensor name='cameraback' type='camera'>
        <update_rate>30</update_rate>
        <camera name='head'>
          <horizontal_fov>1.39626</horizontal_fov>
          <image>
            <width>800</width>
            <height>800</height>
            <format>R8G8B8</format>
          </image>
          <clip>
            <near>0.02</near>
            <far>300</far>
          </clip>
          <noise>
            <type>gaussian</type>
            <mean>0</mean>
            <stddev>0.007</stddev>
          </noise>
        </camera>
        <plugin name='camera_controller' filename='libgazebo_ros_camera.so'>
          <alwaysOn>true</alwaysOn>
          <updateRate>0.0</updateRate>
          <cameraName>ez_rassor/camera_back</cameraName>
          <imageTopicName>image_raw</imageTopicName>
          <cameraInfoTopicName>camera_info</cameraInfoTopicName>
          <frameName>camera_back</frameName>
          <hackBaseline>0.07</hackBaseline>
          <distortionK1>0.0</distortionK1>
          <distortionK2>0.0</distortionK2>
          <distortionK3>0.0</distortionK3>
          <distortionT1>0.0</distortionT1>
          <distortionT2>0.0</distortionT2>
          <robotNamespace>/</robotNamespace>
        </plugin>
        <pose frame=''>-0.5 0.000319 0 0 -0 3.14</pose>
      </sensor>
      <visual name='base_link_fixed_joint_lump__arm_back_visual_visual_1'>
        <pose frame=''>-0.3 8e-05 0 -3.14157 1.57079 -0.000869</pose>
        <geometry>
          <cylinder>
            <length>0.3</length>
            <radius>0.025</radius>
          </cylinder>
        </geometry>
        <material>
          <script>
            <name>Gazebo/White</name>
            <uri>file://media/materials/scripts/gazebo.material</uri>
          </script>
          <ambient>0 0 0 1</ambient>
          <diffuse>0 0 0 1</diffuse>
          <specular>0.1 0.1 0.1 1</specular>
          <emissive>0 0 0 1</emissive>
          <shader type='vertex'>
            <normal_map>__default__</normal_map>
          </shader>
        </material>
        <cast_shadows>1</cast_shadows>
        <transparency>0</transparency>
      </visual>
      <visual name='base_link_visual_visual'>
        <pose frame=''>0 0 0 0 -0 0</pose>
        <geometry>
          <box>
            <size>0.4 0.2 0.1</size>
          </box>
        </geometry>
        <material>
          <script>
            <name>Gazebo/White</name>
            <uri>file://media/materials/scripts/gazebo.material</uri>
          </script>
          <ambient>0 0 0 1</ambient>
          <diffuse>0 0 0 1</diffuse>
          <specular>0.1 0.1 0.1 1</specular>
          <emissive>0 0 0 1</emissive>
          <shader type='vertex'>
            <normal_map>__default__</normal_map>
          </shader>
        </material>
        <cast_shadows>1</cast_shadows>
        <transparency>0</transparency>
      </visual>
      <visual name='base_link_fixed_joint_lump__arm_front_visual_visual_4'>
        <pose frame=''>0.3 -8e-05 0 -3.14157 1.57079 -0.000869</pose>
        <geometry>
          <cylinder>
            <length>0.3</length>
            <radius>0.025</radius>
          </cylinder>
        </geometry>
        <material>
          <script>
            <name>Gazebo/White</name>
            <uri>file://media/materials/scripts/gazebo.material</uri>
          </script>
          <ambient>0 0 0 1</ambient>
          <diffuse>0 0 0 1</diffuse>
          <specular>0.1 0.1 0.1 1</specular>
          <emissive>0 0 0 1</emissive>
          <shader type='vertex'>
            <normal_map>__default__</normal_map>
          </shader>
        </material>
        <cast_shadows>1</cast_shadows>
        <transparency>0</transparency>
      </visual>
      <visual name='base_link_fixed_joint_lump__drum_back_visual_2'>
        <pose frame=''>-0.4 0.000159 0 -3.14075 1.57079 1.56995</pose>
        <geometry>
          <cylinder>
            <length>0.4</length>
            <radius>0.08</radius>
          </cylinder>
        </geometry>
        <material>
          <script>
            <name>Gazebo/Orange</name>
            <uri>file://media/materials/scripts/gazebo.material</uri>
          </script>
          <ambient>1 0.509 0.047 1</ambient>
          <diffuse>1 0.509 0.047 1</diffuse>
          <specular>0.5 0.5 0.5 1</specular>
          <emissive>0 0 0 1</emissive>
          <shader type='vertex'>
            <normal_map>__default__</normal_map>
          </shader>
        </material>
        <cast_shadows>1</cast_shadows>
        <transparency>0</transparency>
      </visual>
      <visual name='base_link_fixed_joint_lump__camera_back_visual_3'>
        <pose frame=''>-0.5 0.000319 0 0 -0 3.14</pose>
        <geometry>
          <box>
            <size>0.1 0.1 0.1</size>
          </box>
        </geometry>
        <material>
          <script>
            <name>Gazebo/Blue</name>
            <uri>file://media/materials/scripts/gazebo.material</uri>
          </script>
          <ambient>0 0 1 1</ambient>
          <diffuse>0 0 1 1</diffuse>
          <specular>0.1 0.1 0.1 1</specular>
          <emissive>0 0 0 1</emissive>
          <shader type='vertex'>
            <normal_map>__default__</normal_map>
          </shader>
        </material>
        <cast_shadows>1</cast_shadows>
        <transparency>0</transparency>
      </visual>
      <visual name='base_link_fixed_joint_lump__drum_front_visual_visual_5'>
        <pose frame=''>0.4 -0.000159 0 -3.14075 1.57079 1.56995</pose>
        <geometry>
          <cylinder>
            <length>0.4</length>
            <radius>0.08</radius>
          </cylinder>
        </geometry>
        <material>
          <script>
            <name>Gazebo/Orange</name>
            <uri>file://media/materials/scripts/gazebo.material</uri>
          </script>
          <ambient>1 0.509 0.047 1</ambient>
          <diffuse>1 0.509 0.047 1</diffuse>
          <specular>0.5 0.5 0.5 1</specular>
          <emissive>0 0 0 1</emissive>
          <shader type='vertex'>
            <normal_map>__default__</normal_map>
          </shader>
        </material>
        <cast_shadows>1</cast_shadows>
        <transparency>0</transparency>
      </visual>
      <collision name='base_link_fixed_joint_lump__collision_collision_1'>
        <laser_retro>0</laser_retro>
        <max_contacts>10</max_contacts>
        <pose frame=''>-0.3 8e-05 0 3.14159 1.57079 -0.000893</pose>
        <geometry>
          <cylinder>
            <radius>0.025</radius>
            <length>0.3</length>
          </cylinder>
        </geometry>
        <surface>
          <friction>
            <ode>
              <mu>1</mu>
              <mu2>1</mu2>
              <fdir1>0 0 0</fdir1>
              <slip1>0</slip1>
              <slip2>0</slip2>
            </ode>
            <torsional>
              <coefficient>1</coefficient>
              <patch_radius>0</patch_radius>
              <surface_radius>0</surface_radius>
              <use_patch_radius>1</use_patch_radius>
              <ode>
                <slip>0</slip>
              </ode>
            </torsional>
          </friction>
          <bounce>
            <restitution_coefficient>0</restitution_coefficient>
            <threshold>1e+06</threshold>
          </bounce>
          <contact>
            <collide_without_contact>0</collide_without_contact>
            <collide_without_contact_bitmask>1</collide_without_contact_bitmask>
            <collide_bitmask>1</collide_bitmask>
            <ode>
              <soft_cfm>0</soft_cfm>
              <soft_erp>0.2</soft_erp>
              <kp>1e+13</kp>
              <kd>1</kd>
              <max_vel>0.01</max_vel>
              <min_depth>0</min_depth>
            </ode>
            <bullet>
              <split_impulse>1</split_impulse>
              <split_impulse_penetration_threshold>-0.01</split_impulse_penetration_threshold>
              <soft_cfm>0</soft_cfm>
              <soft_erp>0.2</soft_erp>
              <kp>1e+13</kp>
              <kd>1</kd>
            </bullet>
          </contact>
        </surface>
      </collision>
      <collision name='base_link_fixed_joint_lump__camera_back_collision_3'>
        <laser_retro>0</laser_retro>
        <max_contacts>10</max_contacts>
        <pose frame=''>-0.5 0.000319 0 3.14159 1.57079 1.56841</pose>
        <geometry>
          <box>
            <size>0.1 0.1 0.1</size>
          </box>
        </geometry>
        <surface>
          <friction>
            <ode>
              <mu>1</mu>
              <mu2>1</mu2>
              <fdir1>0 0 0</fdir1>
              <slip1>0</slip1>
              <slip2>0</slip2>
            </ode>
            <torsional>
              <coefficient>1</coefficient>
              <patch_radius>0</patch_radius>
              <surface_radius>0</surface_radius>
              <use_patch_radius>1</use_patch_radius>
              <ode>
                <slip>0</slip>
              </ode>
            </torsional>
          </friction>
          <bounce>
            <restitution_coefficient>0</restitution_coefficient>
            <threshold>1e+06</threshold>
          </bounce>
          <contact>
            <collide_without_contact>0</collide_without_contact>
            <collide_without_contact_bitmask>1</collide_without_contact_bitmask>
            <collide_bitmask>1</collide_bitmask>
            <ode>
              <soft_cfm>0</soft_cfm>
              <soft_erp>0.2</soft_erp>
              <kp>1e+13</kp>
              <kd>1</kd>
              <max_vel>0.01</max_vel>
              <min_depth>0</min_depth>
            </ode>
            <bullet>
              <split_impulse>1</split_impulse>
              <split_impulse_penetration_threshold>-0.01</split_impulse_penetration_threshold>
              <soft_cfm>0</soft_cfm>
              <soft_erp>0.2</soft_erp>
              <kp>1e+13</kp>
              <kd>1</kd>
            </bullet>
          </contact>
        </surface>
      </collision>
      <collision name='base_link_fixed_joint_lump__collision_collision'>
        <laser_retro>0</laser_retro>
        <max_contacts>10</max_contacts>
        <pose frame=''>0 0 0 0 -0 0</pose>
        <geometry>
          <box>
            <size>0.4 0.2 0.1</size>
          </box>
        </geometry>
        <surface>
          <friction>
            <ode>
              <mu>1</mu>
              <mu2>1</mu2>
              <fdir1>0 0 0</fdir1>
              <slip1>0</slip1>
              <slip2>0</slip2>
            </ode>
            <torsional>
              <coefficient>1</coefficient>
              <patch_radius>0</patch_radius>
              <surface_radius>0</surface_radius>
              <use_patch_radius>1</use_patch_radius>
              <ode>
                <slip>0</slip>
              </ode>
            </torsional>
          </friction>
          <bounce>
            <restitution_coefficient>0</restitution_coefficient>
            <threshold>1e+06</threshold>
          </bounce>
          <contact>
            <collide_without_contact>0</collide_without_contact>
            <collide_without_contact_bitmask>1</collide_without_contact_bitmask>
            <collide_bitmask>1</collide_bitmask>
            <ode>
              <soft_cfm>0</soft_cfm>
              <soft_erp>0.2</soft_erp>
              <kp>1e+13</kp>
              <kd>1</kd>
              <max_vel>0.01</max_vel>
              <min_depth>0</min_depth>
            </ode>
            <bullet>
              <split_impulse>1</split_impulse>
              <split_impulse_penetration_threshold>-0.01</split_impulse_penetration_threshold>
              <soft_cfm>0</soft_cfm>
              <soft_erp>0.2</soft_erp>
              <kp>1e+13</kp>
              <kd>1</kd>
            </bullet>
          </contact>
        </surface>
      </collision>
      <collision name='base_link_fixed_joint_lump__collision_collision_2'>
        <laser_retro>0</laser_retro>
        <max_contacts>10</max_contacts>
        <pose frame=''>-0.4 0.000159 0 -3.14159 1.57079 1.56911</pose>
        <geometry>
          <cylinder>
            <radius>0.07</radius>
            <length>0.05</length>
          </cylinder>
        </geometry>
        <surface>
          <friction>
            <ode>
              <mu>1</mu>
              <mu2>1</mu2>
              <fdir1>0 0 0</fdir1>
              <slip1>0</slip1>
              <slip2>0</slip2>
            </ode>
            <torsional>
              <coefficient>1</coefficient>
              <patch_radius>0</patch_radius>
              <surface_radius>0</surface_radius>
              <use_patch_radius>1</use_patch_radius>
              <ode>
                <slip>0</slip>
              </ode>
            </torsional>
          </friction>
          <bounce>
            <restitution_coefficient>0</restitution_coefficient>
            <threshold>1e+06</threshold>
          </bounce>
          <contact>
            <collide_without_contact>0</collide_without_contact>
            <collide_without_contact_bitmask>1</collide_without_contact_bitmask>
            <collide_bitmask>1</collide_bitmask>
            <ode>
              <soft_cfm>0</soft_cfm>
              <soft_erp>0.2</soft_erp>
              <kp>1e+13</kp>
              <kd>1</kd>
              <max_vel>0.01</max_vel>
              <min_depth>0</min_depth>
            </ode>
            <bullet>
              <split_impulse>1</split_impulse>
              <split_impulse_penetration_threshold>-0.01</split_impulse_penetration_threshold>
              <soft_cfm>0</soft_cfm>
              <soft_erp>0.2</soft_erp>
              <kp>1e+13</kp>
              <kd>1</kd>
            </bullet>
          </contact>
        </surface>
      </collision>
      <collision name='base_link_fixed_joint_lump__collision_collision_4'>
        <laser_retro>0</laser_retro>
        <max_contacts>10</max_contacts>
        <pose frame=''>0.3 -8e-05 0 3.14159 1.57079 -0.000893</pose>
        <geometry>
          <cylinder>
            <radius>0.025</radius>
            <length>0.3</length>
          </cylinder>
        </geometry>
        <surface>
          <friction>
            <ode>
              <mu>1</mu>
              <mu2>1</mu2>
              <fdir1>0 0 0</fdir1>
              <slip1>0</slip1>
              <slip2>0</slip2>
            </ode>
            <torsional>
              <coefficient>1</coefficient>
              <patch_radius>0</patch_radius>
              <surface_radius>0</surface_radius>
              <use_patch_radius>1</use_patch_radius>
              <ode>
                <slip>0</slip>
              </ode>
            </torsional>
          </friction>
          <bounce>
            <restitution_coefficient>0</restitution_coefficient>
            <threshold>1e+06</threshold>
          </bounce>
          <contact>
            <collide_without_contact>0</collide_without_contact>
            <collide_without_contact_bitmask>1</collide_without_contact_bitmask>
            <collide_bitmask>1</collide_bitmask>
            <ode>
              <soft_cfm>0</soft_cfm>
              <soft_erp>0.2</soft_erp>
              <kp>1e+13</kp>
              <kd>1</kd>
              <max_vel>0.01</max_vel>
              <min_depth>0</min_depth>
            </ode>
            <bullet>
              <split_impulse>1</split_impulse>
              <split_impulse_penetration_threshold>-0.01</split_impulse_penetration_threshold>
              <soft_cfm>0</soft_cfm>
              <soft_erp>0.2</soft_erp>
              <kp>1e+13</kp>
              <kd>1</kd>
            </bullet>
          </contact>
        </surface>
      </collision>
      <collision name='base_link_fixed_joint_lump__collision_collision_5'>
        <laser_retro>0</laser_retro>
        <max_contacts>10</max_contacts>
        <pose frame=''>0.4 -0.000159 0 -3.14159 1.57079 1.56911</pose>
        <geometry>
          <cylinder>
            <radius>0.07</radius>
            <length>0.05</length>
          </cylinder>
        </geometry>
        <surface>
          <friction>
            <ode>
              <mu>1</mu>
              <mu2>1</mu2>
              <fdir1>0 0 0</fdir1>
              <slip1>0</slip1>
              <slip2>0</slip2>
            </ode>
            <torsional>
              <coefficient>1</coefficient>
              <patch_radius>0</patch_radius>
              <surface_radius>0</surface_radius>
              <use_patch_radius>1</use_patch_radius>
              <ode>
                <slip>0</slip>
              </ode>
            </torsional>
          </friction>
          <bounce>
            <restitution_coefficient>0</restitution_coefficient>
            <threshold>1e+06</threshold>
          </bounce>
          <contact>
            <collide_without_contact>0</collide_without_contact>
            <collide_without_contact_bitmask>1</collide_without_contact_bitmask>
            <collide_bitmask>1</collide_bitmask>
            <ode>
              <soft_cfm>0</soft_cfm>
              <soft_erp>0.2</soft_erp>
              <kp>1e+13</kp>
              <kd>1</kd>
              <max_vel>0.01</max_vel>
              <min_depth>0</min_depth>
            </ode>
            <bullet>
              <split_impulse>1</split_impulse>
              <split_impulse_penetration_threshold>-0.01</split_impulse_penetration_threshold>
              <soft_cfm>0</soft_cfm>
              <soft_erp>0.2</soft_erp>
              <kp>1e+13</kp>
              <kd>1</kd>
            </bullet>
          </contact>
        </surface>
      </collision>
    </link>
    <link name='left_wheel_back'>
      <pose frame=''>-0.15 0.15 -0 0 -0 0</pose>
      <inertial>
        <pose frame=''>0 0 0 -0 1.5707 1.5707</pose>
        <mass>0.5</mass>
        <inertia>
          <ixx>0.00135417</ixx>
          <ixy>0</ixy>
          <ixz>0</ixz>
          <iyy>0.00135417</iyy>
          <iyz>0</iyz>
          <izz>0.0025</izz>
        </inertia>
      </inertial>
      <self_collide>0</self_collide>
      <kinematic>0</kinematic>
      <visual name='left_wheel_back_visual_visual'>
        <pose frame=''>0 -0.06 0 -3.12268 1.57079 -1.55198</pose>
        <geometry>
          <mesh>
            <scale>1 1 1</scale>
            <uri>model://meshes/wheel.dae</uri>
          </mesh>
        </geometry>
        <cast_shadows>1</cast_shadows>
        <transparency>0</transparency>
        <material>
          <shader type='vertex'>
            <normal_map>__default__</normal_map>
          </shader>
        </material>
      </visual>
      <collision name='left_wheel_back_fixed_joint_lump__collision_collision'>
        <laser_retro>0</laser_retro>
        <max_contacts>10</max_contacts>
        <pose frame=''>0 -0.06 0 3.14159 1.57079 -1.57089</pose>
        <geometry>
          <mesh>
            <uri>model://meshes/wheel.dae</uri>
          </mesh>
        </geometry>
        <surface>
          <friction>
            <ode>
              <mu>1</mu>
              <mu2>1</mu2>
              <fdir1>0 0 0</fdir1>
              <slip1>0</slip1>
              <slip2>0</slip2>
            </ode>
            <torsional>
              <coefficient>1</coefficient>
              <patch_radius>0</patch_radius>
              <surface_radius>0</surface_radius>
              <use_patch_radius>1</use_patch_radius>
              <ode>
                <slip>0</slip>
              </ode>
            </torsional>
          </friction>
          <bounce>
            <restitution_coefficient>0</restitution_coefficient>
            <threshold>1e+06</threshold>
          </bounce>
          <contact>
            <collide_without_contact>0</collide_without_contact>
            <collide_without_contact_bitmask>1</collide_without_contact_bitmask>
            <collide_bitmask>1</collide_bitmask>
            <ode>
              <soft_cfm>0</soft_cfm>
              <soft_erp>0.2</soft_erp>
              <kp>1e+13</kp>
              <kd>1</kd>
              <max_vel>0.01</max_vel>
              <min_depth>0</min_depth>
            </ode>
            <bullet>
              <split_impulse>1</split_impulse>
              <split_impulse_penetration_threshold>-0.01</split_impulse_penetration_threshold>
              <soft_cfm>0</soft_cfm>
              <soft_erp>0.2</soft_erp>
              <kp>1e+13</kp>
              <kd>1</kd>
            </bullet>
          </contact>
        </surface>
      </collision>
    </link>
    <link name='left_wheel_front'>
      <pose frame=''>0.15 0.15 0 0 -0 0</pose>
      <inertial>
        <pose frame=''>0 0 0 -0 1.5707 1.5707</pose>
        <mass>0.5</mass>
        <inertia>
          <ixx>0.00135417</ixx>
          <ixy>0</ixy>
          <ixz>0</ixz>
          <iyy>0.00135417</iyy>
          <iyz>0</iyz>
          <izz>0.0025</izz>
        </inertia>
      </inertial>
      <self_collide>0</self_collide>
      <kinematic>0</kinematic>
      <visual name='left_wheel_front_visual_visual'>
        <pose frame=''>0 -0.06 0 -3.12268 1.57079 -1.55198</pose>
        <geometry>
          <mesh>
            <scale>1 1 1</scale>
            <uri>model://meshes/wheel.dae</uri>
          </mesh>
        </geometry>
        <cast_shadows>1</cast_shadows>
        <transparency>0</transparency>
        <material>
          <shader type='vertex'>
            <normal_map>__default__</normal_map>
          </shader>
        </material>
      </visual>
      <collision name='left_wheel_front_fixed_joint_lump__collision_collision'>
        <laser_retro>0</laser_retro>
        <max_contacts>10</max_contacts>
        <pose frame=''>0 -0.06 0 3.14159 1.57079 -1.57089</pose>
        <geometry>
          <mesh>
            <uri>model://meshes/wheel.dae</uri>
          </mesh>
        </geometry>
        <surface>
          <friction>
            <ode>
              <mu>1</mu>
              <mu2>1</mu2>
              <fdir1>0 0 0</fdir1>
              <slip1>0</slip1>
              <slip2>0</slip2>
            </ode>
            <torsional>
              <coefficient>1</coefficient>
              <patch_radius>0</patch_radius>
              <surface_radius>0</surface_radius>
              <use_patch_radius>1</use_patch_radius>
              <ode>
                <slip>0</slip>
              </ode>
            </torsional>
          </friction>
          <bounce>
            <restitution_coefficient>0</restitution_coefficient>
            <threshold>1e+06</threshold>
          </bounce>
          <contact>
            <collide_without_contact>0</collide_without_contact>
            <collide_without_contact_bitmask>1</collide_without_contact_bitmask>
            <collide_bitmask>1</collide_bitmask>
            <ode>
              <soft_cfm>0</soft_cfm>
              <soft_erp>0.2</soft_erp>
              <kp>1e+13</kp>
              <kd>1</kd>
              <max_vel>0.01</max_vel>
              <min_depth>0</min_depth>
            </ode>
            <bullet>
              <split_impulse>1</split_impulse>
              <split_impulse_penetration_threshold>-0.01</split_impulse_penetration_threshold>
              <soft_cfm>0</soft_cfm>
              <soft_erp>0.2</soft_erp>
              <kp>1e+13</kp>
              <kd>1</kd>
            </bullet>
          </contact>
        </surface>
      </collision>
    </link>
    <link name='right_wheel_back'>
      <pose frame=''>-0.15 -0.15 -0 0 -0 0</pose>
      <inertial>
        <pose frame=''>0 0 0 -0 1.5707 1.5707</pose>
        <mass>0.5</mass>
        <inertia>
          <ixx>0.00135417</ixx>
          <ixy>0</ixy>
          <ixz>0</ixz>
          <iyy>0.00135417</iyy>
          <iyz>0</iyz>
          <izz>0.0025</izz>
        </inertia>
      </inertial>
      <self_collide>0</self_collide>
      <kinematic>0</kinematic>
      <visual name='right_wheel_back_visual_visual'>
        <pose frame=''>0 0.06 0 -0.00702 1.57079 -1.57316</pose>
        <geometry>
          <mesh>
            <scale>1 1 1</scale>
            <uri>model://meshes/wheel.dae</uri>
          </mesh>
        </geometry>
        <cast_shadows>1</cast_shadows>
        <transparency>0</transparency>
        <material>
          <shader type='vertex'>
            <normal_map>__default__</normal_map>
          </shader>
        </material>
      </visual>
      <collision name='right_wheel_back_fixed_joint_lump__collision_collision'>
        <laser_retro>0</laser_retro>
        <max_contacts>10</max_contacts>
        <pose frame=''>0 0.06 0 0 1.57079 -1.57089</pose>
        <geometry>
          <mesh>
            <uri>model://meshes/wheel.dae</uri>
          </mesh>
        </geometry>
        <surface>
          <friction>
            <ode>
              <mu>1</mu>
              <mu2>1</mu2>
              <fdir1>0 0 0</fdir1>
              <slip1>0</slip1>
              <slip2>0</slip2>
            </ode>
            <torsional>
              <coefficient>1</coefficient>
              <patch_radius>0</patch_radius>
              <surface_radius>0</surface_radius>
              <use_patch_radius>1</use_patch_radius>
              <ode>
                <slip>0</slip>
              </ode>
            </torsional>
          </friction>
          <bounce>
            <restitution_coefficient>0</restitution_coefficient>
            <threshold>1e+06</threshold>
          </bounce>
          <contact>
            <collide_without_contact>0</collide_without_contact>
            <collide_without_contact_bitmask>1</collide_without_contact_bitmask>
            <collide_bitmask>1</collide_bitmask>
            <ode>
              <soft_cfm>0</soft_cfm>
              <soft_erp>0.2</soft_erp>
              <kp>1e+13</kp>
              <kd>1</kd>
              <max_vel>0.01</max_vel>
              <min_depth>0</min_depth>
            </ode>
            <bullet>
              <split_impulse>1</split_impulse>
              <split_impulse_penetration_threshold>-0.01</split_impulse_penetration_threshold>
              <soft_cfm>0</soft_cfm>
              <soft_erp>0.2</soft_erp>
              <kp>1e+13</kp>
              <kd>1</kd>
            </bullet>
          </contact>
        </surface>
      </collision>
    </link>
    <link name='right_wheel_front'>
      <pose frame=''>0.15 -0.15 0 0 -0 0</pose>
      <inertial>
        <pose frame=''>0 0 0 -0 1.5707 1.5707</pose>
        <mass>0.5</mass>
        <inertia>
          <ixx>0.00135417</ixx>
          <ixy>0</ixy>
          <ixz>0</ixz>
          <iyy>0.00135417</iyy>
          <iyz>0</iyz>
          <izz>0.0025</izz>
        </inertia>
      </inertial>
      <self_collide>0</self_collide>
      <kinematic>0</kinematic>
      <visual name='right_wheel_front_visual_visual'>
        <pose frame=''>0 0.06 0 -0.007023 1.57079 -1.57316</pose>
        <geometry>
          <mesh>
            <scale>1 1 1</scale>
            <uri>model://meshes/wheel.dae</uri>
          </mesh>
        </geometry>
        <cast_shadows>1</cast_shadows>
        <transparency>0</transparency>
        <material>
          <shader type='vertex'>
            <normal_map>__default__</normal_map>
          </shader>
        </material>
      </visual>
      <collision name='right_wheel_front_fixed_joint_lump__collision_collision'>
        <laser_retro>0</laser_retro>
        <max_contacts>10</max_contacts>
        <pose frame=''>0 0.06 0 0 1.57079 -1.57089</pose>
        <geometry>
          <mesh>
            <uri>model://meshes/wheel.dae</uri>
          </mesh>
        </geometry>
        <surface>
          <friction>
            <ode>
              <mu>1</mu>
              <mu2>1</mu2>
              <fdir1>0 0 0</fdir1>
              <slip1>0</slip1>
              <slip2>0</slip2>
            </ode>
            <torsional>
              <coefficient>1</coefficient>
              <patch_radius>0</patch_radius>
              <surface_radius>0</surface_radius>
              <use_patch_radius>1</use_patch_radius>
              <ode>
                <slip>0</slip>
              </ode>
            </torsional>
          </friction>
          <bounce>
            <restitution_coefficient>0</restitution_coefficient>
            <threshold>1e+06</threshold>
          </bounce>
          <contact>
            <collide_without_contact>0</collide_without_contact>
            <collide_without_contact_bitmask>1</collide_without_contact_bitmask>
            <collide_bitmask>1</collide_bitmask>
            <ode>
              <soft_cfm>0</soft_cfm>
              <soft_erp>0.2</soft_erp>
              <kp>1e+13</kp>
              <kd>1</kd>
              <max_vel>0.01</max_vel>
              <min_depth>0</min_depth>
            </ode>
            <bullet>
              <split_impulse>1</split_impulse>
              <split_impulse_penetration_threshold>-0.01</split_impulse_penetration_threshold>
              <soft_cfm>0</soft_cfm>
              <soft_erp>0.2</soft_erp>
              <kp>1e+13</kp>
              <kd>1</kd>
            </bullet>
          </contact>
        </surface>
      </collision>
    </link>
    <joint name='left_wheel_back_hinge' type='revolute'>
      <parent>base_link</parent>
      <child>left_wheel_back</child>
      <pose frame=''>0 0 0 0 -0 0</pose>
      <axis>
        <xyz>0 1 0</xyz>
        <use_parent_model_frame>1</use_parent_model_frame>
        <limit>
          <lower>-1e+16</lower>
          <upper>1e+16</upper>
          <effort>-1</effort>
          <velocity>-1</velocity>
        </limit>
        <dynamics>
          <spring_reference>0</spring_reference>
          <spring_stiffness>0</spring_stiffness>
          <damping>0</damping>
          <friction>0</friction>
        </dynamics>
      </axis>
      <physics>
        <ode>
          <limit>
            <cfm>0</cfm>
            <erp>0.2</erp>
          </limit>
          <suspension>
            <cfm>0</cfm>
            <erp>0.2</erp>
          </suspension>
        </ode>
      </physics>
    </joint>
    <joint name='left_wheel_front_hinge' type='revolute'>
      <parent>base_link</parent>
      <child>left_wheel_front</child>
      <pose frame=''>0 0 0 0 -0 0</pose>
      <axis>
        <xyz>0 1 0</xyz>
        <use_parent_model_frame>1</use_parent_model_frame>
        <limit>
          <lower>-1e+16</lower>
          <upper>1e+16</upper>
          <effort>-1</effort>
          <velocity>-1</velocity>
        </limit>
        <dynamics>
          <spring_reference>0</spring_reference>
          <spring_stiffness>0</spring_stiffness>
          <damping>0</damping>
          <friction>0</friction>
        </dynamics>
      </axis>
      <physics>
        <ode>
          <limit>
            <cfm>0</cfm>
            <erp>0.2</erp>
          </limit>
          <suspension>
            <cfm>0</cfm>
            <erp>0.2</erp>
          </suspension>
        </ode>
      </physics>
    </joint>
    <joint name='right_wheel_back_hinge' type='revolute'>
      <parent>base_link</parent>
      <child>right_wheel_back</child>
      <pose frame=''>0 0 0 0 -0 0</pose>
      <axis>
        <xyz>0 1 0</xyz>
        <use_parent_model_frame>1</use_parent_model_frame>
        <limit>
          <lower>-1e+16</lower>
          <upper>1e+16</upper>
          <effort>-1</effort>
          <velocity>-1</velocity>
        </limit>
        <dynamics>
          <spring_reference>0</spring_reference>
          <spring_stiffness>0</spring_stiffness>
          <damping>0</damping>
          <friction>0</friction>
        </dynamics>
      </axis>
      <physics>
        <ode>
          <limit>
            <cfm>0</cfm>
            <erp>0.2</erp>
          </limit>
          <suspension>
            <cfm>0</cfm>
            <erp>0.2</erp>
          </suspension>
        </ode>
      </physics>
    </joint>
    <joint name='right_wheel_front_hinge' type='revolute'>
      <parent>base_link</parent>
      <child>right_wheel_front</child>
      <pose frame=''>0 0 0 0 -0 0</pose>
      <axis>
        <xyz>0 1 0</xyz>
        <use_parent_model_frame>1</use_parent_model_frame>
        <limit>
          <lower>-1e+16</lower>
          <upper>1e+16</upper>
          <effort>-1</effort>
          <velocity>-1</velocity>
        </limit>
        <dynamics>
          <spring_reference>0</spring_reference>
          <spring_stiffness>0</spring_stiffness>
          <damping>0</damping>
          <friction>0</friction>
        </dynamics>
      </axis>
      <physics>
        <ode>
          <limit>
            <cfm>0</cfm>
            <erp>0.2</erp>
          </limit>
          <suspension>
            <cfm>0</cfm>
            <erp>0.2</erp>
          </suspension>
        </ode>
      </physics>
    </joint>
    <static>0</static>
    <allow_auto_disable>1</allow_auto_disable>
    <plugin name='gazebo_ros_control' filename='libgazebo_ros_control.so'>
      <robotNamespace>/ez_rassor</robotNamespace>
    </plugin>
  </model>
</sdf>
