<sdf version='1.6'>
  <world name='moon'>
    <light name='sun' type='directional'>
      <cast_shadows>1</cast_shadows>
      <pose frame=''>0 0 10 0 -0 0</pose>
      <diffuse>0.8 0.8 0.8 1</diffuse>
      <specular>0.1 0.1 0.1 1</specular>
      <attenuation>
        <range>1000</range>
        <constant>0.9</constant>
        <linear>0.01</linear>
        <quadratic>0.001</quadratic>
      </attenuation>
      <direction>-0.5 0.5 -1</direction>
    </light>
    <model name='apollo15_landing_site_1000x1000'>
      <static>1</static>
      <link name='link'>
        <collision name='collision'>
          <surface>
            <friction>
              <ode>
                <mu>0.2</mu>
              </ode>
              <torsional>
                <ode/>
              </torsional>
            </friction>
            <contact>
              <ode>
                <soft_cfm>1</soft_cfm>
                <kp>100000</kp>
                <kd>1</kd>
                <max_vel>1e-06</max_vel>
                <min_depth>0.02</min_depth>
              </ode>
            </contact>
            <bounce/>
          </surface>
          <geometry>
            <heightmap>
              <uri>model://apollo15_landing_site_1000x1000/materials/textures/NAC_DTM_APOLLO15_E261N0036_257x257+7472+2152.png</uri>
              <size>514 514 49</size>
              <pos>0 0 -45</pos>
              <texture>
                <size>10</size>
                <diffuse>__default__</diffuse>
                <normal>__default__</normal>
              </texture>
              <blend>
                <min_height>0</min_height>
                <fade_dist>0</fade_dist>
              </blend>
            </heightmap>
          </geometry>
          <max_contacts>10</max_contacts>
        </collision>
        <visual name='visual'>
          <geometry>
            <heightmap>
              <texture>
                <diffuse>model://apollo15_landing_site_1000x1000/materials/textures/AS16-110-18026HR-512x512.jpg</diffuse>
                <normal>file://media/materials/textures/flat_normal.png</normal>
                <size>2</size>
              </texture>
              <uri>model://apollo15_landing_site_1000x1000/materials/textures/NAC_DTM_APOLLO15_E261N0036_257x257+7472+2152.png</uri>
              <size>514 514 49</size>
              <pos>0 0 -45</pos>
              <blend>
                <min_height>0</min_height>
                <fade_dist>0</fade_dist>
              </blend>
            </heightmap>
          </geometry>
        </visual>
        <self_collide>0</self_collide>
        <kinematic>0</kinematic>
        <gravity>1</gravity>
      </link>
    </model>
    <light name='sun' type='directional'>
      <cast_shadows>1</cast_shadows>
      <pose frame=''>0 0 10 0 -0 0</pose>
      <diffuse>0.8 0.8 0.8 1</diffuse>
      <specular>0.1 0.1 0.1 1</specular>
      <attenuation>
        <range>1000</range>
        <constant>0.9</constant>
        <linear>0.01</linear>
        <quadratic>0.001</quadratic>
      </attenuation>
      <direction>-0.5 0.5 -1</direction>
    </light>
    <physics name='default_physics' default='0' type='ode'>
      <max_step_size>0.01</max_step_size>
      <real_time_factor>1</real_time_factor>
      <real_time_update_rate>100</real_time_update_rate>
    </physics>
    <gravity>0 0 -1.622</gravity>
    <magnetic_field>6e-06 2.3e-05 -4.2e-05</magnetic_field>
    <atmosphere type='adiabatic'/>
    <scene>
      <ambient>0.4 0.4 0.4 1</ambient>
      <background>0.7 0.7 0.7 1</background>
      <shadows>1</shadows>
    </scene>
    <spherical_coordinates>
      <surface_model>EARTH_WGS84</surface_model>
      <latitude_deg>0</latitude_deg>
      <longitude_deg>0</longitude_deg>
      <elevation>0</elevation>
      <heading_deg>0</heading_deg>
    </spherical_coordinates>
    <model name='ez_rassor'>
      <link name='base_link'>
        <pose frame=''>0 0 0 0 -0 0</pose>
        <inertial>
          <pose frame=''>-0 0 0.097087 0 -0 0</pose>
          <mass>10.3</mass>
          <inertia>
            <ixx>0.502914</ixx>
            <ixy>-1.03398e-25</ixy>
            <ixz>-6.73679e-19</ixz>
            <iyy>1.04709</iyy>
            <iyz>0</iyz>
            <izz>0.144181</izz>
          </inertia>
        </inertial>
        <collision name='base_link_fixed_joint_lump__collision_collision'>
          <pose frame=''>0 0 0 0 -0 0</pose>
          <geometry>
            <box>
              <size>0.4 0.2 0.1</size>
            </box>
          </geometry>
          <max_contacts>10</max_contacts>
          <surface>
            <contact>
              <ode/>
            </contact>
            <bounce/>
            <friction>
              <torsional>
                <ode/>
              </torsional>
              <ode/>
            </friction>
          </surface>
        </collision>
        <collision name='base_link_fixed_joint_lump__stereo_camera_back_collision_1'>
          <pose frame=''>-0.47 0 0 0 -0 3.14</pose>
          <geometry>
            <box>
              <size>0.005 0.005 0.005</size>
            </box>
          </geometry>
          <surface>
            <contact>
              <ode/>
            </contact>
            <friction>
              <ode/>
              <torsional>
                <ode/>
              </torsional>
            </friction>
            <bounce/>
          </surface>
          <max_contacts>10</max_contacts>
        </collision>
        <collision name='base_link_fixed_joint_lump__stereo_camera_front_collision_2'>
          <pose frame=''>0.47 0 0 0 -0 0</pose>
          <geometry>
            <box>
              <size>0.005 0.005 0.005</size>
            </box>
          </geometry>
          <surface>
            <contact>
              <ode/>
            </contact>
            <friction>
              <ode/>
              <torsional>
                <ode/>
              </torsional>
            </friction>
            <bounce/>
          </surface>
          <max_contacts>10</max_contacts>
        </collision>
        <collision name='base_link_fixed_joint_lump__imu_link_collision_3'>
          <pose frame=''>0 0 0 0 -0 0</pose>
          <geometry>
            <box>
              <size>0.005 0.005 0.005</size>
            </box>
          </geometry>
          <surface>
            <contact>
              <ode/>
            </contact>
            <friction>
              <ode/>
              <torsional>
                <ode/>
              </torsional>
            </friction>
            <bounce/>
          </surface>
          <max_contacts>10</max_contacts>
        </collision>
        <visual name='base_link_visual_visual'>
          <pose frame=''>0 0 0 0 -0 0</pose>
          <geometry>
            <box>
              <size>0.4 0.2 0.1</size>
            </box>
          </geometry>
          <material>
            <script>
              <name>Gazebo/Black</name>
              <uri>file://media/materials/scripts/gazebo.material</uri>
            </script>
          </material>
        </visual>
        <visual name='base_link_fixed_joint_lump__stereo_camera_back_visual_1'>
          <pose frame=''>-0.47 0 0 0 -0 3.14</pose>
          <geometry>
            <box>
              <size>0.005 0.005 0.005</size>
            </box>
          </geometry>
          <material>
            <script>
              <uri>__default__</uri>
              <name>__default__</name>
            </script>
          </material>
        </visual>
        <visual name='base_link_fixed_joint_lump__stereo_camera_front_visual_2'>
          <pose frame=''>0.47 0 0 0 -0 0</pose>
          <geometry>
            <box>
              <size>0.005 0.005 0.005</size>
            </box>
          </geometry>
          <material>
            <script>
              <uri>__default__</uri>
              <name>__default__</name>
            </script>
          </material>
        </visual>
        <visual name='base_link_fixed_joint_lump__imu_link_visual_3'>
          <pose frame=''>0 0 0 0 -0 0</pose>
          <geometry>
            <box>
              <size>0.005 0.005 0.005</size>
            </box>
          </geometry>
          <material>
            <script>
              <uri>__default__</uri>
              <name>__default__</name>
            </script>
          </material>
        </visual>
        <velocity_decay/>
        <velocity_decay/>
        <sensor name='stereo_camera' type='multicamera'>
          <update_rate>30</update_rate>
          <camera name='left'>
            <pose frame=''>0 0.035 0 0 -0 0</pose>
            <horizontal_fov>1.39626</horizontal_fov>
            <image>
              <width>800</width>
              <height>800</height>
              <format>R8G8B8</format>
            </image>
            <clip>
              <near>0.02</near>
              <far>300</far>
            </clip>
            <noise>
              <type>gaussian</type>
              <mean>0</mean>
              <stddev>0.007</stddev>
            </noise>
          </camera>
          <camera name='right'>
            <pose frame=''>0 -0.035 0 0 -0 0</pose>
            <horizontal_fov>1.39626</horizontal_fov>
            <image>
              <width>800</width>
              <height>800</height>
              <format>R8G8B8</format>
            </image>
            <clip>
              <near>0.02</near>
              <far>300</far>
            </clip>
            <noise>
              <type>gaussian</type>
              <mean>0</mean>
              <stddev>0.007</stddev>
            </noise>
          </camera>
          <plugin name='stereo_camera_controller' filename='libgazebo_ros_multicamera.so'>
            <focalLength>0</focalLength>
            <alwaysOn>true</alwaysOn>
            <updateRate>0.0</updateRate>
            <cameraName>ez_rassor/back_camera</cameraName>
            <imageTopicName>image_raw</imageTopicName>
            <cameraInfoTopicName>camera_info</cameraInfoTopicName>
            <frameName>left_camera_optical_frame</frameName>
            <rightFrameName>right_camera_optical_frame</rightFrameName>
            <hackBaseline>0.07</hackBaseline>
            <distortionK1>0.0</distortionK1>
            <distortionK2>0.0</distortionK2>
            <distortionK3>0.0</distortionK3>
            <distortionT1>0.0</distortionT1>
            <distortionT2>0.0</distortionT2>
            <robotNamespace>/</robotNamespace>
          </plugin>
          <pose frame=''>-0.47 0 0 0 -0 3.14</pose>
        </sensor>
        <velocity_decay/>
        <sensor name='stereo_camera' type='multicamera'>
          <update_rate>30</update_rate>
          <camera name='left'>
            <pose frame=''>0 0.035 0 0 -0 0</pose>
            <horizontal_fov>1.39626</horizontal_fov>
            <image>
              <width>800</width>
              <height>800</height>
              <format>R8G8B8</format>
            </image>
            <clip>
              <near>0.02</near>
              <far>300</far>
            </clip>
            <noise>
              <type>gaussian</type>
              <mean>0</mean>
              <stddev>0.007</stddev>
            </noise>
          </camera>
          <camera name='right'>
            <pose frame=''>0 -0.035 0 0 -0 0</pose>
            <horizontal_fov>1.39626</horizontal_fov>
            <image>
              <width>800</width>
              <height>800</height>
              <format>R8G8B8</format>
            </image>
            <clip>
              <near>0.02</near>
              <far>300</far>
            </clip>
            <noise>
              <type>gaussian</type>
              <mean>0</mean>
              <stddev>0.007</stddev>
            </noise>
          </camera>
          <plugin name='stereo_camera_controller' filename='libgazebo_ros_multicamera.so'>
            <focalLength>0</focalLength>
            <alwaysOn>true</alwaysOn>
            <updateRate>0.0</updateRate>
            <cameraName>ez_rassor/front_camera</cameraName>
            <imageTopicName>image_raw</imageTopicName>
            <cameraInfoTopicName>camera_info</cameraInfoTopicName>
            <frameName>left_camera_optical_frame</frameName>
            <rightFrameName>right_camera_optical_frame</rightFrameName>
            <hackBaseline>0.07</hackBaseline>
            <distortionK1>0.0</distortionK1>
            <distortionK2>0.0</distortionK2>
            <distortionK3>0.0</distortionK3>
            <distortionT1>0.0</distortionT1>
            <distortionT2>0.0</distortionT2>
            <robotNamespace>/</robotNamespace>
          </plugin>
          <pose frame=''>0.47 0 0 0 -0 0</pose>
        </sensor>
        <gravity>1</gravity>
        <velocity_decay/>
        <self_collide>0</self_collide>
        <gravity>1</gravity>
        <sensor name='imu_sensor' type='imu'>
          <always_on>1</always_on>
          <update_rate>100</update_rate>
          <visualize>1</visualize>
          <topic>__default_topic__</topic>
          <plugin name='imu_plugin' filename='libgazebo_ros_imu_sensor.so'>
            <topicName>imu</topicName>
            <bodyName>imu_link</bodyName>
            <updateRateHZ>10.0</updateRateHZ>
            <gaussianNoise>0.0</gaussianNoise>
            <xyzOffset>0 0 0</xyzOffset>
            <rpyOffset>0 0 0</rpyOffset>
            <frameName>imu_link</frameName>
            <robotNamespace>/</robotNamespace>
          </plugin>
          <pose frame=''>0 0 0 0 -0 0</pose>
        </sensor>
        <kinematic>0</kinematic>
      </link>
      <link name='arm_back'>
        <pose frame=''>-0.25 0 0 0 -0 -0.000385</pose>
        <inertial>
          <pose frame=''>0 0 0 0 -0 3.1415</pose>
          <mass>5</mass>
          <inertia>
            <ixx>0.0135417</ixx>
            <ixy>0</ixy>
            <ixz>0</ixz>
            <iyy>0.0135417</iyy>
            <iyz>0</iyz>
            <izz>0.025</izz>
          </inertia>
        </inertial>
        <collision name='arm_back_fixed_joint_lump__collision_collision'>
          <pose frame=''>0 0 0 0 -0 3.1415</pose>
          <geometry>
            <mesh>
              <scale>1 1 1</scale>
              <uri>/home/cameron/.workspace/src/ez_rassor_description/meshes/drum_arm_short.dae</uri>
            </mesh>
          </geometry>
          <max_contacts>10</max_contacts>
          <surface>
            <contact>
              <ode/>
            </contact>
            <bounce/>
            <friction>
              <torsional>
                <ode/>
              </torsional>
              <ode/>
            </friction>
          </surface>
        </collision>
        <visual name='arm_back_fixed_joint_lump__visual_visual'>
          <pose frame=''>0 0 0 0 -0 3.1415</pose>
          <geometry>
            <mesh>
              <scale>1 1 1</scale>
              <uri>/home/cameron/.workspace/src/ez_rassor_description/meshes/drum_arm_short.dae</uri>
            </mesh>
          </geometry>
        </visual>
        <gravity>1</gravity>
        <velocity_decay/>
        <self_collide>0</self_collide>
        <kinematic>0</kinematic>
      </link>
      <joint name='arm_back_hinge' type='revolute'>
        <child>arm_back</child>
        <parent>base_link</parent>
        <axis>
          <xyz>0.000385 1 0</xyz>
          <limit>
            <lower>-1e+16</lower>
            <upper>1e+16</upper>
          </limit>
          <dynamics>
            <spring_reference>0</spring_reference>
            <spring_stiffness>0</spring_stiffness>
          </dynamics>
          <use_parent_model_frame>1</use_parent_model_frame>
        </axis>
      </joint>
      <link name='drum_back'>
        <pose frame=''>-0.588245 0.00013 0 0 -0 -0.000771</pose>
        <inertial>
          <pose frame=''>0 0 0 0 -0 -1.57099</pose>
          <mass>5</mass>
          <inertia>
            <ixx>0.0135417</ixx>
            <ixy>0</ixy>
            <ixz>0</ixz>
            <iyy>0.0135417</iyy>
            <iyz>0</iyz>
            <izz>0.025</izz>
          </inertia>
        </inertial>
        <collision name='drum_back_fixed_joint_lump__collision_collision'>
          <pose frame=''>0 0 0 0 -0 -1.57099</pose>
          <geometry>
            <mesh>
              <scale>1 1 1</scale>
              <uri>/home/cameron/.workspace/src/ez_rassor_description/meshes/drum.dae</uri>
            </mesh>
          </geometry>
          <max_contacts>10</max_contacts>
          <surface>
            <contact>
              <ode/>
            </contact>
            <bounce/>
            <friction>
              <torsional>
                <ode/>
              </torsional>
              <ode/>
            </friction>
          </surface>
        </collision>
        <visual name='drum_back_visual'>
          <pose frame=''>0 0 0 0 -0 -1.57099</pose>
          <geometry>
            <mesh>
              <scale>1 1 1</scale>
              <uri>/home/cameron/.workspace/src/ez_rassor_description/meshes/drum.dae</uri>
            </mesh>
          </geometry>
          <material>
            <script>
              <name>Gazebo/Orange</name>
              <uri>file://media/materials/scripts/gazebo.material</uri>
            </script>
          </material>
        </visual>
        <gravity>1</gravity>
        <velocity_decay/>
        <self_collide>0</self_collide>
        <kinematic>0</kinematic>
      </link>
      <joint name='drum_back_hinge' type='revolute'>
        <child>drum_back</child>
        <parent>arm_back</parent>
        <axis>
          <xyz>0.000771 1 0</xyz>
          <limit>
            <lower>-1e+16</lower>
            <upper>1e+16</upper>
          </limit>
          <dynamics>
            <spring_reference>0</spring_reference>
            <spring_stiffness>0</spring_stiffness>
          </dynamics>
          <use_parent_model_frame>1</use_parent_model_frame>
        </axis>
      </joint>
      <link name='arm_front'>
        <pose frame=''>0.25 0 0 0 -0 -0.000385</pose>
        <inertial>
          <pose frame=''>0 0 0 0 -0 0</pose>
          <mass>5</mass>
          <inertia>
            <ixx>0.0135417</ixx>
            <ixy>0</ixy>
            <ixz>0</ixz>
            <iyy>0.0135417</iyy>
            <iyz>0</iyz>
            <izz>0.025</izz>
          </inertia>
        </inertial>
        <collision name='arm_front_fixed_joint_lump__collision_collision'>
          <pose frame=''>0 0 0 0 -0 0</pose>
          <geometry>
            <mesh>
              <scale>1 1 1</scale>
              <uri>/home/cameron/.workspace/src/ez_rassor_description/meshes/drum_arm_short.dae</uri>
            </mesh>
          </geometry>
          <max_contacts>10</max_contacts>
          <surface>
            <contact>
              <ode/>
            </contact>
            <bounce/>
            <friction>
              <torsional>
                <ode/>
              </torsional>
              <ode/>
            </friction>
          </surface>
        </collision>
        <visual name='arm_front_fixed_joint_lump__visual_visual'>
          <pose frame=''>0 0 0 0 -0 0</pose>
          <geometry>
            <mesh>
              <scale>1 1 1</scale>
              <uri>/home/cameron/.workspace/src/ez_rassor_description/meshes/drum_arm_short.dae</uri>
            </mesh>
          </geometry>
        </visual>
        <gravity>1</gravity>
        <velocity_decay/>
        <self_collide>0</self_collide>
        <kinematic>0</kinematic>
      </link>
      <joint name='arm_front_hinge' type='revolute'>
        <child>arm_front</child>
        <parent>base_link</parent>
        <axis>
          <xyz>0.000385 1 0</xyz>
          <limit>
            <lower>-1e+16</lower>
            <upper>1e+16</upper>
          </limit>
          <dynamics>
            <spring_reference>0</spring_reference>
            <spring_stiffness>0</spring_stiffness>
          </dynamics>
          <use_parent_model_frame>1</use_parent_model_frame>
        </axis>
      </joint>
      <link name='drum_front'>
        <pose frame=''>0.588245 -0.00013 0 0 -0 -0.000771</pose>
        <inertial>
          <pose frame=''>0 0 0 0 -0 1.5707</pose>
          <mass>5</mass>
          <inertia>
            <ixx>0.0135417</ixx>
            <ixy>0</ixy>
            <ixz>0</ixz>
            <iyy>0.0135417</iyy>
            <iyz>0</iyz>
            <izz>0.025</izz>
          </inertia>
        </inertial>
        <collision name='drum_front_fixed_joint_lump__collision_collision'>
          <pose frame=''>0 0 0 0 -0 1.5707</pose>
          <geometry>
            <mesh>
              <scale>1 1 1</scale>
              <uri>/home/cameron/.workspace/src/ez_rassor_description/meshes/drum.dae</uri>
            </mesh>
          </geometry>
          <max_contacts>10</max_contacts>
          <surface>
            <contact>
              <ode/>
            </contact>
            <bounce/>
            <friction>
              <torsional>
                <ode/>
              </torsional>
              <ode/>
            </friction>
          </surface>
        </collision>
        <visual name='drum_front_visual_visual'>
          <pose frame=''>0 0 0 0 -0 1.5707</pose>
          <geometry>
            <mesh>
              <scale>1 1 1</scale>
              <uri>/home/cameron/.workspace/src/ez_rassor_description/meshes/drum.dae</uri>
            </mesh>
          </geometry>
          <material>
            <script>
              <name>Gazebo/Orange</name>
              <uri>file://media/materials/scripts/gazebo.material</uri>
            </script>
          </material>
        </visual>
        <gravity>1</gravity>
        <velocity_decay/>
        <self_collide>0</self_collide>
        <kinematic>0</kinematic>
      </link>
      <joint name='drum_front_hinge' type='revolute'>
        <child>drum_front</child>
        <parent>arm_front</parent>
        <axis>
          <xyz>0.000771 1 0</xyz>
          <limit>
            <lower>-1e+16</lower>
            <upper>1e+16</upper>
          </limit>
          <dynamics>
            <spring_reference>0</spring_reference>
            <spring_stiffness>0</spring_stiffness>
          </dynamics>
          <use_parent_model_frame>1</use_parent_model_frame>
        </axis>
      </joint>
      <link name='left_wheel_back'>
        <pose frame=''>-0.15 0.15 0 0 -0 0</pose>
        <inertial>
          <pose frame=''>0 0 0 -0 1.5707 1.5707</pose>
          <mass>5</mass>
          <inertia>
            <ixx>0.0135417</ixx>
            <ixy>0</ixy>
            <ixz>0</ixz>
            <iyy>0.0135417</iyy>
            <iyz>0</iyz>
            <izz>0.025</izz>
          </inertia>
        </inertial>
        <collision name='left_wheel_back_fixed_joint_lump__collision_collision'>
          <pose frame=''>0 -0.06 0 3.14159 1.57079 -1.57089</pose>
          <geometry>
            <mesh>
              <scale>1 1 1</scale>
              <uri>/home/cameron/.workspace/src/ez_rassor_description/meshes/wheel.dae</uri>
            </mesh>
          </geometry>
          <max_contacts>10</max_contacts>
          <surface>
            <contact>
              <ode/>
            </contact>
            <bounce/>
            <friction>
              <torsional>
                <ode/>
              </torsional>
              <ode/>
            </friction>
          </surface>
        </collision>
        <visual name='left_wheel_back_visual_visual'>
          <pose frame=''>0 -0.06 0 3.14159 1.57079 -1.57089</pose>
          <geometry>
            <mesh>
              <scale>1 1 1</scale>
              <uri>/home/cameron/.workspace/src/ez_rassor_description/meshes/wheel.dae</uri>
            </mesh>
          </geometry>
        </visual>
        <self_collide>0</self_collide>
        <kinematic>0</kinematic>
        <gravity>1</gravity>
      </link>
      <joint name='left_wheel_back_hinge' type='revolute'>
        <child>left_wheel_back</child>
        <parent>base_link</parent>
        <axis>
          <xyz>0 1 0</xyz>
          <limit>
            <lower>-1e+16</lower>
            <upper>1e+16</upper>
          </limit>
          <dynamics>
            <spring_reference>0</spring_reference>
            <spring_stiffness>0</spring_stiffness>
          </dynamics>
          <use_parent_model_frame>1</use_parent_model_frame>
        </axis>
      </joint>
      <link name='left_wheel_front'>
        <pose frame=''>0.15 0.15 0 0 -0 0</pose>
        <inertial>
          <pose frame=''>0 0 0 -0 1.5707 1.5707</pose>
          <mass>5</mass>
          <inertia>
            <ixx>0.0135417</ixx>
            <ixy>0</ixy>
            <ixz>0</ixz>
            <iyy>0.0135417</iyy>
            <iyz>0</iyz>
            <izz>0.025</izz>
          </inertia>
        </inertial>
        <collision name='left_wheel_front_fixed_joint_lump__collision_collision'>
          <pose frame=''>0 -0.06 0 3.14159 1.57079 -1.57089</pose>
          <geometry>
            <mesh>
              <scale>1 1 1</scale>
              <uri>/home/cameron/.workspace/src/ez_rassor_description/meshes/wheel.dae</uri>
            </mesh>
          </geometry>
          <max_contacts>10</max_contacts>
          <surface>
            <contact>
              <ode/>
            </contact>
            <bounce/>
            <friction>
              <torsional>
                <ode/>
              </torsional>
              <ode/>
            </friction>
          </surface>
        </collision>
        <visual name='left_wheel_front_visual_visual'>
          <pose frame=''>0 -0.06 0 3.14159 1.57079 -1.57089</pose>
          <geometry>
            <mesh>
              <scale>1 1 1</scale>
              <uri>/home/cameron/.workspace/src/ez_rassor_description/meshes/wheel.dae</uri>
            </mesh>
          </geometry>
        </visual>
        <self_collide>0</self_collide>
        <kinematic>0</kinematic>
        <gravity>1</gravity>
      </link>
      <joint name='left_wheel_front_hinge' type='revolute'>
        <child>left_wheel_front</child>
        <parent>base_link</parent>
        <axis>
          <xyz>0 1 0</xyz>
          <limit>
            <lower>-1e+16</lower>
            <upper>1e+16</upper>
          </limit>
          <dynamics>
            <spring_reference>0</spring_reference>
            <spring_stiffness>0</spring_stiffness>
          </dynamics>
          <use_parent_model_frame>1</use_parent_model_frame>
        </axis>
      </joint>
      <link name='right_wheel_back'>
        <pose frame=''>-0.15 -0.15 0 0 -0 0</pose>
        <inertial>
          <pose frame=''>0 0 0 -0 1.5707 1.5707</pose>
          <mass>5</mass>
          <inertia>
            <ixx>0.0135417</ixx>
            <ixy>0</ixy>
            <ixz>0</ixz>
            <iyy>0.0135417</iyy>
            <iyz>0</iyz>
            <izz>0.025</izz>
          </inertia>
        </inertial>
        <collision name='right_wheel_back_fixed_joint_lump__collision_collision'>
          <pose frame=''>0 0.06 0 -3.14159 1.57079 1.5707</pose>
          <geometry>
            <mesh>
              <scale>1 1 1</scale>
              <uri>/home/cameron/.workspace/src/ez_rassor_description/meshes/wheel.dae</uri>
            </mesh>
          </geometry>
          <max_contacts>10</max_contacts>
          <surface>
            <contact>
              <ode/>
            </contact>
            <bounce/>
            <friction>
              <torsional>
                <ode/>
              </torsional>
              <ode/>
            </friction>
          </surface>
        </collision>
        <visual name='right_wheel_back_visual_visual'>
          <pose frame=''>0 0.06 0 -3.14159 1.57079 1.57545</pose>
          <geometry>
            <mesh>
              <scale>1 1 1</scale>
              <uri>/home/cameron/.workspace/src/ez_rassor_description/meshes/wheel.dae</uri>
            </mesh>
          </geometry>
        </visual>
        <self_collide>0</self_collide>
        <kinematic>0</kinematic>
        <gravity>1</gravity>
      </link>
      <joint name='right_wheel_back_hinge' type='revolute'>
        <child>right_wheel_back</child>
        <parent>base_link</parent>
        <axis>
          <xyz>0 1 0</xyz>
          <limit>
            <lower>-1e+16</lower>
            <upper>1e+16</upper>
          </limit>
          <dynamics>
            <spring_reference>0</spring_reference>
            <spring_stiffness>0</spring_stiffness>
          </dynamics>
          <use_parent_model_frame>1</use_parent_model_frame>
        </axis>
      </joint>
      <link name='right_wheel_front'>
        <pose frame=''>0.15 -0.15 0 0 -0 0</pose>
        <inertial>
          <pose frame=''>0 0 0 -0 1.5707 1.5707</pose>
          <mass>5</mass>
          <inertia>
            <ixx>0.0135417</ixx>
            <ixy>0</ixy>
            <ixz>0</ixz>
            <iyy>0.0135417</iyy>
            <iyz>0</iyz>
            <izz>0.025</izz>
          </inertia>
        </inertial>
        <collision name='right_wheel_front_fixed_joint_lump__collision_collision'>
          <pose frame=''>0 0.06 0 -3.14159 1.57079 1.5707</pose>
          <geometry>
            <mesh>
              <scale>1 1 1</scale>
              <uri>/home/cameron/.workspace/src/ez_rassor_description/meshes/wheel.dae</uri>
            </mesh>
          </geometry>
          <max_contacts>10</max_contacts>
          <surface>
            <contact>
              <ode/>
            </contact>
            <bounce/>
            <friction>
              <torsional>
                <ode/>
              </torsional>
              <ode/>
            </friction>
          </surface>
        </collision>
        <visual name='right_wheel_front_visual_visual'>
          <pose frame=''>0 0.06 0 -3.14159 1.57079 1.57545</pose>
          <geometry>
            <mesh>
              <scale>1 1 1</scale>
              <uri>/home/cameron/.workspace/src/ez_rassor_description/meshes/wheel.dae</uri>
            </mesh>
          </geometry>
        </visual>
        <self_collide>0</self_collide>
        <kinematic>0</kinematic>
        <gravity>1</gravity>
      </link>
      <joint name='right_wheel_front_hinge' type='revolute'>
        <child>right_wheel_front</child>
        <parent>base_link</parent>
        <axis>
          <xyz>0 1 0</xyz>
          <limit>
            <lower>-1e+16</lower>
            <upper>1e+16</upper>
          </limit>
          <dynamics>
            <spring_reference>0</spring_reference>
            <spring_stiffness>0</spring_stiffness>
          </dynamics>
          <use_parent_model_frame>1</use_parent_model_frame>
        </axis>
      </joint>
      <static>0</static>
      <plugin name='gazebo_ros_control' filename='libgazebo_ros_control.so'>
        <robotNamespace>/ez_rassor</robotNamespace>
      </plugin>
      <pose frame=''>0 0 0 0 -0 0</pose>
    </model>
    <model name='textured_shapes'>
      <pose frame=''>-2.48537 0.110222 0.5 0 -0 0</pose>
      <link name='box'>
        <pose frame=''>0 -1.5 0 0 -0 0</pose>
        <collision name='collision'>
          <geometry>
            <box>
              <size>1 1 1</size>
            </box>
          </geometry>
          <max_contacts>10</max_contacts>
          <surface>
            <contact>
              <ode/>
            </contact>
            <bounce/>
            <friction>
              <torsional>
                <ode/>
              </torsional>
              <ode/>
            </friction>
          </surface>
        </collision>
        <visual name='visual'>
          <geometry>
            <box>
              <size>1 1 1</size>
            </box>
          </geometry>
          <material>
            <script>
              <uri>model://textured_shapes/materials/scripts</uri>
              <uri>model://textured_shapes/materials/textures</uri>
              <name>TexturedShape/Squares</name>
            </script>
          </material>
        </visual>
        <self_collide>0</self_collide>
        <inertial>
          <inertia>
            <ixx>1</ixx>
            <ixy>0</ixy>
            <ixz>0</ixz>
            <iyy>1</iyy>
            <iyz>0</iyz>
            <izz>1</izz>
          </inertia>
          <mass>1</mass>
        </inertial>
        <kinematic>0</kinematic>
        <gravity>1</gravity>
      </link>
      <link name='sphere'>
        <collision name='collision'>
          <geometry>
            <sphere>
              <radius>0.5</radius>
            </sphere>
          </geometry>
          <max_contacts>10</max_contacts>
          <surface>
            <contact>
              <ode/>
            </contact>
            <bounce/>
            <friction>
              <torsional>
                <ode/>
              </torsional>
              <ode/>
            </friction>
          </surface>
        </collision>
        <visual name='visual'>
          <geometry>
            <sphere>
              <radius>0.5</radius>
            </sphere>
          </geometry>
          <material>
            <script>
              <uri>model://textured_shapes/materials/scripts</uri>
              <uri>model://textured_shapes/materials/textures</uri>
              <name>TexturedShape/Squares</name>
            </script>
          </material>
        </visual>
        <self_collide>0</self_collide>
        <inertial>
          <inertia>
            <ixx>1</ixx>
            <ixy>0</ixy>
            <ixz>0</ixz>
            <iyy>1</iyy>
            <iyz>0</iyz>
            <izz>1</izz>
          </inertia>
          <mass>1</mass>
        </inertial>
        <kinematic>0</kinematic>
        <gravity>1</gravity>
      </link>
      <link name='cylinder'>
        <pose frame=''>0 1.5 0 0 -0 0</pose>
        <collision name='collision'>
          <geometry>
            <cylinder>
              <radius>0.5</radius>
              <length>1</length>
            </cylinder>
          </geometry>
          <max_contacts>10</max_contacts>
          <surface>
            <contact>
              <ode/>
            </contact>
            <bounce/>
            <friction>
              <torsional>
                <ode/>
              </torsional>
              <ode/>
            </friction>
          </surface>
        </collision>
        <visual name='visual'>
          <geometry>
            <cylinder>
              <radius>0.5</radius>
              <length>1</length>
            </cylinder>
          </geometry>
          <material>
            <script>
              <uri>model://textured_shapes/materials/scripts</uri>
              <uri>model://textured_shapes/materials/textures</uri>
              <name>TexturedShape/Squares</name>
            </script>
          </material>
        </visual>
        <self_collide>0</self_collide>
        <inertial>
          <inertia>
            <ixx>1</ixx>
            <ixy>0</ixy>
            <ixz>0</ixz>
            <iyy>1</iyy>
            <iyz>0</iyz>
            <izz>1</izz>
          </inertia>
          <mass>1</mass>
        </inertial>
        <kinematic>0</kinematic>
        <gravity>1</gravity>
      </link>
    </model>
    <state world_name='moon'>
      <sim_time>351 740000000</sim_time>
      <real_time>352 960261946</real_time>
      <wall_time>1549120319 93493034</wall_time>
      <iterations>35174</iterations>
      <model name='apollo15_landing_site_1000x1000'>
        <pose frame=''>0 0 0 0 -0 0</pose>
        <scale>1 1 1</scale>
        <link name='link'>
          <pose frame=''>0 0 0 0 -0 0</pose>
          <velocity>0 0 0 0 -0 0</velocity>
          <acceleration>0 0 0 0 -0 0</acceleration>
          <wrench>0 0 0 0 -0 0</wrench>
        </link>
      </model>
      <model name='ez_rassor'>
        <pose frame=''>-0.116852 0.078493 0.44788 -0.095616 -0.146041 -0.017938</pose>
        <scale>1 1 1</scale>
        <link name='arm_back'>
          <pose frame=''>-0.364149 0.082921 0.411498 -0.102483 0.393177 -0.071786</pose>
          <velocity>-3.3e-05 1.3e-05 8.6e-05 0.000114 0.003982 -0.000266</velocity>
          <acceleration>0.000141 0.000311 -1.3e-05 -2.6e-05 2.6e-05 0.000616</acceleration>
          <wrench>0.000705 0.001554 -6.4e-05 0 -0 0</wrench>
        </link>
        <link name='arm_front'>
          <pose frame=''>0.130446 0.074071 0.484255 -0.098297 -0.276577 -0.005231</pose>
          <velocity>-2.6e-05 3.7e-05 5.1e-05 -1.8e-05 0.000228 6e-05</velocity>
          <acceleration>0.00014 -8.7e-05 -0.000409 0.00257 -0.003362 0.001683</acceleration>
          <wrench>0.000701 -0.000435 -0.002043 0 -0 0</wrench>
        </link>
        <link name='base_link'>
          <pose frame=''>-0.116852 0.078493 0.44788 -0.095616 -0.146041 -0.017938</pose>
          <velocity>-3e-05 2.9e-05 6.8e-05 -4.5e-05 7.3e-05 6.6e-05</velocity>
          <acceleration>0.000261 0.000214 -0.000214 -1.2e-05 0.000905 0.000471</acceleration>
          <wrench>0.002685 0.002209 -0.002202 0 -0 0</wrench>
        </link>
        <link name='drum_back'>
          <pose frame=''>-0.675816 0.105312 0.54107 -2.12576 1.45921 -2.16132</pose>
          <velocity>0.000517 8.7e-05 0.001345 -0.000499 -0.014648 0.00151</velocity>
          <acceleration>0.000345 0.000132 0.000127 0.000176 5.6e-05 0.001201</acceleration>
          <wrench>0.001726 0.000658 0.000636 0 -0 0</wrench>
        </link>
        <link name='drum_front'>
          <pose frame=''>0.455813 0.072321 0.576638 -1.85586 1.47214 -1.88948</pose>
          <velocity>-2.8e-05 5.7e-05 -3e-06 -0.000109 -0.000675 0.000134</velocity>
          <acceleration>0.000373 -7.2e-05 0.000267 0.004193 -0.003619 0.010983</acceleration>
          <wrench>0.001866 -0.000362 0.001334 0 -0 0</wrench>
        </link>
        <link name='left_wheel_back'>
          <pose frame=''>-0.260484 0.230399 0.41187 -0.173809 -0.996953 0.114603</pose>
          <velocity>-4.5e-05 1.8e-05 6.8e-05 -0.000112 -0.000353 2.3e-05</velocity>
          <acceleration>0.000185 0.000267 -4.6e-05 -0.002492 0.002119 -0.001194</acceleration>
          <wrench>0.000924 0.001337 -0.000228 0 -0 0</wrench>
        </link>
        <link name='left_wheel_front'>
          <pose frame=''>0.036283 0.225088 0.455512 -0.220977 -1.12179 0.167644</pose>
          <velocity>-5e-05 3.4e-05 5.2e-05 -6.8e-05 -0.000338 0.000149</velocity>
          <acceleration>0.000255 -0.000733 -0.000502 -0.025462 0.001076 -0.011577</acceleration>
          <wrench>0.001274 -0.003665 -0.002509 0 -0 0</wrench>
        </link>
        <link name='right_wheel_back'>
          <pose frame=''>-0.269982 -0.068161 0.440197 -0.111379 -0.548177 0.026463</pose>
          <velocity>-1.9e-05 1.4e-05 0.000103 -8.3e-05 9.3e-05 0.000231</velocity>
          <acceleration>0.000128 0.00015 1.1e-05 -0.001336 0.001024 -0.000354</acceleration>
          <wrench>0.00064 0.000749 5.4e-05 0 -0 0</wrench>
        </link>
        <link name='right_wheel_front'>
          <pose frame=''>0.026763 -0.073419 0.483886 -0.094957 -0.08597 -0.023716</pose>
          <velocity>-1.6e-05 3.9e-05 5.7e-05 -2.3e-05 -1e-06 7e-05</velocity>
          <acceleration>0.00023 0.000136 -0.000343 -3e-06 0.0008 -0.00014</acceleration>
          <wrench>0.001152 0.000678 -0.001716 0 -0 0</wrench>
        </link>
      </model>
      <model name='textured_shapes'>
        <pose frame=''>-2.54163 0.181211 0.592984 -0.094665 -0.095732 -0.00334</pose>
        <scale>1 1 1</scale>
        <link name='box'>
          <pose frame=''>-2.56017 -1.31202 0.73412 -0.094665 -0.095732 -0.00334</pose>
          <velocity>0 0 0 0 -0 0</velocity>
          <acceleration>0 0 0 0 -0 0</acceleration>
          <wrench>0 0 0 0 -0 0</wrench>
        </link>
        <link name='cylinder'>
          <pose frame=''>-2.97087 4.38387 -0.302738 -1.28356 -0.924317 -0.149976</pose>
          <velocity>0 0 0 0 -0 0</velocity>
          <acceleration>0.033756 -0.123297 -0.680257 0.499524 -0.062688 -0.026113</acceleration>
          <wrench>0.033756 -0.123297 -0.680257 0 -0 0</wrench>
        </link>
        <link name='sphere'>
          <pose frame=''>-2.42165 5.29636 -1.40002 -0.550762 -1.25476 0.581059</pose>
          <velocity>0.062439 0.023068 1.5e-05 0.046134 -0.124874 0.115316</velocity>
          <acceleration>0 0 0 0 -0 0</acceleration>
          <wrench>0 0 0 0 -0 0</wrench>
        </link>
      </model>
      <light name='sun'>
        <pose frame=''>0 0 10 0 -0 0</pose>
      </light>
    </state>
    <gui fullscreen='0'>
      <camera name='user_camera'>
        <pose frame=''>6.76287 3.83814 5.56231 0 0.563456 -2.73099</pose>
        <view_controller>orbit</view_controller>
        <projection_type>perspective</projection_type>
      </camera>
    </gui>
  </world>
</sdf>
