<sdf version='1.6'>
  <world name='moon'>
    <light name='sun' type='directional'>
      <cast_shadows>1</cast_shadows>
      <pose frame=''>0 0 10 0 -0 0</pose>
      <diffuse>0.8 0.8 0.8 1</diffuse>
      <specular>0.1 0.1 0.1 1</specular>
      <attenuation>
        <range>1000</range>
        <constant>0.9</constant>
        <linear>0.01</linear>
        <quadratic>0.001</quadratic>
      </attenuation>
      <direction>-0.5 0.5 -1</direction>
    </light>
    <model name='apollo15_landing_site_1000x1000'>
      <static>1</static>
      <link name='link'>
        <collision name='collision'>
          <surface>
            <friction>
              <ode>
                <mu>0.2</mu>
              </ode>
              <torsional>
                <ode/>
              </torsional>
            </friction>
            <contact>
              <ode>
                <soft_cfm>1</soft_cfm>
                <kp>100000</kp>
                <kd>1</kd>
                <max_vel>1e-06</max_vel>
                <min_depth>0.02</min_depth>
              </ode>
            </contact>
            <bounce/>
          </surface>
          <geometry>
            <heightmap>
              <uri>model://apollo15_landing_site_1000x1000/materials/textures/NAC_DTM_APOLLO15_E261N0036_257x257+7472+2152.png</uri>
              <size>514 514 49</size>
              <pos>0 0 -45</pos>
              <texture>
                <size>10</size>
                <diffuse>__default__</diffuse>
                <normal>__default__</normal>
              </texture>
              <blend>
                <min_height>0</min_height>
                <fade_dist>0</fade_dist>
              </blend>
            </heightmap>
          </geometry>
          <max_contacts>10</max_contacts>
        </collision>
        <visual name='visual'>
          <geometry>
            <heightmap>
              <texture>
                <diffuse>model://apollo15_landing_site_1000x1000/materials/textures/AS16-110-18026HR-512x512.jpg</diffuse>
                <normal>file://media/materials/textures/flat_normal.png</normal>
                <size>2</size>
              </texture>
              <uri>model://apollo15_landing_site_1000x1000/materials/textures/NAC_DTM_APOLLO15_E261N0036_257x257+7472+2152.png</uri>
              <size>514 514 49</size>
              <pos>0 0 -45</pos>
              <blend>
                <min_height>0</min_height>
                <fade_dist>0</fade_dist>
              </blend>
            </heightmap>
          </geometry>
        </visual>
        <self_collide>0</self_collide>
        <kinematic>0</kinematic>
        <gravity>1</gravity>
      </link>
    </model>
    <light name='sun' type='directional'>
      <cast_shadows>1</cast_shadows>
      <pose frame=''>0 0 10 0 -0 0</pose>
      <diffuse>0.8 0.8 0.8 1</diffuse>
      <specular>0.1 0.1 0.1 1</specular>
      <attenuation>
        <range>1000</range>
        <constant>0.9</constant>
        <linear>0.01</linear>
        <quadratic>0.001</quadratic>
      </attenuation>
      <direction>-0.5 0.5 -1</direction>
    </light>
    <physics name='default_physics' default='0' type='ode'>
      <max_step_size>0.01</max_step_size>
      <real_time_factor>1</real_time_factor>
      <real_time_update_rate>100</real_time_update_rate>
    </physics>
    <gravity>0 0 -1.622</gravity>
    <magnetic_field>6e-06 2.3e-05 -4.2e-05</magnetic_field>
    <atmosphere type='adiabatic'/>
    <scene>
      <ambient>0.4 0.4 0.4 1</ambient>
      <background>0.7 0.7 0.7 1</background>
      <shadows>1</shadows>
    </scene>
    <spherical_coordinates>
      <surface_model>EARTH_WGS84</surface_model>
      <latitude_deg>0</latitude_deg>
      <longitude_deg>0</longitude_deg>
      <elevation>0</elevation>
      <heading_deg>0</heading_deg>
    </spherical_coordinates>
    <model name='ez_rassor'>
      <link name='base_link'>
        <pose frame=''>0 0 0 0 -0 0</pose>
        <inertial>
          <pose frame=''>-0 0 0.097087 0 -0 0</pose>
          <mass>10.3</mass>
          <inertia>
            <ixx>0.502914</ixx>
            <ixy>-1.03398e-25</ixy>
            <ixz>-6.73679e-19</ixz>
            <iyy>1.04709</iyy>
            <iyz>0</iyz>
            <izz>0.144181</izz>
          </inertia>
        </inertial>
        <collision name='base_link_fixed_joint_lump__collision_collision'>
          <pose frame=''>0 0 0 0 -0 0</pose>
          <geometry>
            <box>
              <size>0.4 0.2 0.1</size>
            </box>
          </geometry>
          <max_contacts>10</max_contacts>
          <surface>
            <contact>
              <ode/>
            </contact>
            <bounce/>
            <friction>
              <torsional>
                <ode/>
              </torsional>
              <ode/>
            </friction>
          </surface>
        </collision>
        <collision name='base_link_fixed_joint_lump__stereo_camera_back_collision_1'>
          <pose frame=''>-0.47 0 0 0 -0 3.14</pose>
          <geometry>
            <box>
              <size>0.005 0.005 0.005</size>
            </box>
          </geometry>
          <surface>
            <contact>
              <ode/>
            </contact>
            <friction>
              <ode/>
              <torsional>
                <ode/>
              </torsional>
            </friction>
            <bounce/>
          </surface>
          <max_contacts>10</max_contacts>
        </collision>
        <collision name='base_link_fixed_joint_lump__stereo_camera_front_collision_2'>
          <pose frame=''>0.47 0 0 0 -0 0</pose>
          <geometry>
            <box>
              <size>0.005 0.005 0.005</size>
            </box>
          </geometry>
          <surface>
            <contact>
              <ode/>
            </contact>
            <friction>
              <ode/>
              <torsional>
                <ode/>
              </torsional>
            </friction>
            <bounce/>
          </surface>
          <max_contacts>10</max_contacts>
        </collision>
        <collision name='base_link_fixed_joint_lump__imu_link_collision_3'>
          <pose frame=''>0 0 0 0 -0 0</pose>
          <geometry>
            <box>
              <size>0.005 0.005 0.005</size>
            </box>
          </geometry>
          <surface>
            <contact>
              <ode/>
            </contact>
            <friction>
              <ode/>
              <torsional>
                <ode/>
              </torsional>
            </friction>
            <bounce/>
          </surface>
          <max_contacts>10</max_contacts>
        </collision>
        <visual name='base_link_visual_visual'>
          <pose frame=''>0 0 0 0 -0 0</pose>
          <geometry>
            <box>
              <size>0.4 0.2 0.1</size>
            </box>
          </geometry>
          <material>
            <script>
              <name>Gazebo/Black</name>
              <uri>file://media/materials/scripts/gazebo.material</uri>
            </script>
          </material>
        </visual>
        <visual name='base_link_fixed_joint_lump__stereo_camera_back_visual_1'>
          <pose frame=''>-0.47 0 0 0 -0 3.14</pose>
          <geometry>
            <box>
              <size>0.005 0.005 0.005</size>
            </box>
          </geometry>
          <material>
            <script>
              <uri>__default__</uri>
              <name>__default__</name>
            </script>
          </material>
        </visual>
        <visual name='base_link_fixed_joint_lump__stereo_camera_front_visual_2'>
          <pose frame=''>0.47 0 0 0 -0 0</pose>
          <geometry>
            <box>
              <size>0.005 0.005 0.005</size>
            </box>
          </geometry>
          <material>
            <script>
              <uri>__default__</uri>
              <name>__default__</name>
            </script>
          </material>
        </visual>
        <visual name='base_link_fixed_joint_lump__imu_link_visual_3'>
          <pose frame=''>0 0 0 0 -0 0</pose>
          <geometry>
            <box>
              <size>0.005 0.005 0.005</size>
            </box>
          </geometry>
          <material>
            <script>
              <uri>__default__</uri>
              <name>__default__</name>
            </script>
          </material>
        </visual>
        <velocity_decay/>
        <velocity_decay/>
        <sensor name='stereo_camera' type='multicamera'>
          <update_rate>30</update_rate>
          <camera name='left'>
            <pose frame=''>0 0.035 0 0 -0 0</pose>
            <horizontal_fov>1.39626</horizontal_fov>
            <image>
              <width>800</width>
              <height>800</height>
              <format>R8G8B8</format>
            </image>
            <clip>
              <near>0.02</near>
              <far>300</far>
            </clip>
            <noise>
              <type>gaussian</type>
              <mean>0</mean>
              <stddev>0.007</stddev>
            </noise>
          </camera>
          <camera name='right'>
            <pose frame=''>0 -0.035 0 0 -0 0</pose>
            <horizontal_fov>1.39626</horizontal_fov>
            <image>
              <width>800</width>
              <height>800</height>
              <format>R8G8B8</format>
            </image>
            <clip>
              <near>0.02</near>
              <far>300</far>
            </clip>
            <noise>
              <type>gaussian</type>
              <mean>0</mean>
              <stddev>0.007</stddev>
            </noise>
          </camera>
          <plugin name='stereo_camera_controller' filename='libgazebo_ros_multicamera.so'>
            <focalLength>0</focalLength>
            <alwaysOn>true</alwaysOn>
            <updateRate>0.0</updateRate>
            <cameraName>ez_rassor/back_camera</cameraName>
            <imageTopicName>image_raw</imageTopicName>
            <cameraInfoTopicName>camera_info</cameraInfoTopicName>
            <frameName>left_camera_optical_frame</frameName>
            <rightFrameName>right_camera_optical_frame</rightFrameName>
            <hackBaseline>0.07</hackBaseline>
            <distortionK1>0.0</distortionK1>
            <distortionK2>0.0</distortionK2>
            <distortionK3>0.0</distortionK3>
            <distortionT1>0.0</distortionT1>
            <distortionT2>0.0</distortionT2>
            <robotNamespace>/</robotNamespace>
          </plugin>
          <pose frame=''>-0.47 0 0 0 -0 3.14</pose>
        </sensor>
        <velocity_decay/>
        <sensor name='stereo_camera' type='multicamera'>
          <update_rate>30</update_rate>
          <camera name='left'>
            <pose frame=''>0 0.035 0 0 -0 0</pose>
            <horizontal_fov>1.39626</horizontal_fov>
            <image>
              <width>800</width>
              <height>800</height>
              <format>R8G8B8</format>
            </image>
            <clip>
              <near>0.02</near>
              <far>300</far>
            </clip>
            <noise>
              <type>gaussian</type>
              <mean>0</mean>
              <stddev>0.007</stddev>
            </noise>
          </camera>
          <camera name='right'>
            <pose frame=''>0 -0.035 0 0 -0 0</pose>
            <horizontal_fov>1.39626</horizontal_fov>
            <image>
              <width>800</width>
              <height>800</height>
              <format>R8G8B8</format>
            </image>
            <clip>
              <near>0.02</near>
              <far>300</far>
            </clip>
            <noise>
              <type>gaussian</type>
              <mean>0</mean>
              <stddev>0.007</stddev>
            </noise>
          </camera>
          <plugin name='stereo_camera_controller' filename='libgazebo_ros_multicamera.so'>
            <focalLength>0</focalLength>
            <alwaysOn>true</alwaysOn>
            <updateRate>0.0</updateRate>
            <cameraName>ez_rassor/front_camera</cameraName>
            <imageTopicName>image_raw</imageTopicName>
            <cameraInfoTopicName>camera_info</cameraInfoTopicName>
            <frameName>left_camera_optical_frame</frameName>
            <rightFrameName>right_camera_optical_frame</rightFrameName>
            <hackBaseline>0.07</hackBaseline>
            <distortionK1>0.0</distortionK1>
            <distortionK2>0.0</distortionK2>
            <distortionK3>0.0</distortionK3>
            <distortionT1>0.0</distortionT1>
            <distortionT2>0.0</distortionT2>
            <robotNamespace>/</robotNamespace>
          </plugin>
          <pose frame=''>0.47 0 0 0 -0 0</pose>
        </sensor>
        <gravity>1</gravity>
        <velocity_decay/>
        <self_collide>0</self_collide>
        <gravity>1</gravity>
        <sensor name='imu_sensor' type='imu'>
          <always_on>1</always_on>
          <update_rate>100</update_rate>
          <visualize>1</visualize>
          <topic>__default_topic__</topic>
          <plugin name='imu_plugin' filename='libgazebo_ros_imu_sensor.so'>
            <topicName>imu</topicName>
            <bodyName>imu_link</bodyName>
            <updateRateHZ>10.0</updateRateHZ>
            <gaussianNoise>0.0</gaussianNoise>
            <xyzOffset>0 0 0</xyzOffset>
            <rpyOffset>0 0 0</rpyOffset>
            <frameName>imu_link</frameName>
            <robotNamespace>/</robotNamespace>
          </plugin>
          <pose frame=''>0 0 0 0 -0 0</pose>
        </sensor>
        <kinematic>0</kinematic>
      </link>
      <link name='arm_back'>
        <pose frame=''>-0.25 0 0 0 -0 -0.000385</pose>
        <inertial>
          <pose frame=''>0 0 0 0 -0 3.1415</pose>
          <mass>5</mass>
          <inertia>
            <ixx>0.0135417</ixx>
            <ixy>0</ixy>
            <ixz>0</ixz>
            <iyy>0.0135417</iyy>
            <iyz>0</iyz>
            <izz>0.025</izz>
          </inertia>
        </inertial>
        <collision name='arm_back_fixed_joint_lump__collision_collision'>
          <pose frame=''>0 0 0 0 -0 3.1415</pose>
          <geometry>
            <mesh>
              <scale>1 1 1</scale>
              <uri>/home/cameron/.workspace/src/ez_rassor_description/meshes/drum_arm_short.dae</uri>
            </mesh>
          </geometry>
          <max_contacts>10</max_contacts>
          <surface>
            <contact>
              <ode/>
            </contact>
            <bounce/>
            <friction>
              <torsional>
                <ode/>
              </torsional>
              <ode/>
            </friction>
          </surface>
        </collision>
        <visual name='arm_back_fixed_joint_lump__visual_visual'>
          <pose frame=''>0 0 0 0 -0 3.1415</pose>
          <geometry>
            <mesh>
              <scale>1 1 1</scale>
              <uri>/home/cameron/.workspace/src/ez_rassor_description/meshes/drum_arm_short.dae</uri>
            </mesh>
          </geometry>
        </visual>
        <gravity>1</gravity>
        <velocity_decay/>
        <self_collide>0</self_collide>
        <kinematic>0</kinematic>
      </link>
      <joint name='arm_back_hinge' type='revolute'>
        <child>arm_back</child>
        <parent>base_link</parent>
        <axis>
          <xyz>0.000385 1 0</xyz>
          <limit>
            <lower>-1e+16</lower>
            <upper>1e+16</upper>
          </limit>
          <dynamics>
            <spring_reference>0</spring_reference>
            <spring_stiffness>0</spring_stiffness>
          </dynamics>
          <use_parent_model_frame>1</use_parent_model_frame>
        </axis>
      </joint>
      <link name='drum_back'>
        <pose frame=''>-0.588245 0.00013 0 0 -0 -0.000771</pose>
        <inertial>
          <pose frame=''>0 0 0 0 -0 -1.57099</pose>
          <mass>5</mass>
          <inertia>
            <ixx>0.0135417</ixx>
            <ixy>0</ixy>
            <ixz>0</ixz>
            <iyy>0.0135417</iyy>
            <iyz>0</iyz>
            <izz>0.025</izz>
          </inertia>
        </inertial>
        <collision name='drum_back_fixed_joint_lump__collision_collision'>
          <pose frame=''>0 0 0 0 -0 -1.57099</pose>
          <geometry>
            <mesh>
              <scale>1 1 1</scale>
              <uri>/home/cameron/.workspace/src/ez_rassor_description/meshes/drum.dae</uri>
            </mesh>
          </geometry>
          <max_contacts>10</max_contacts>
          <surface>
            <contact>
              <ode/>
            </contact>
            <bounce/>
            <friction>
              <torsional>
                <ode/>
              </torsional>
              <ode/>
            </friction>
          </surface>
        </collision>
        <visual name='drum_back_visual'>
          <pose frame=''>0 0 0 0 -0 -1.57099</pose>
          <geometry>
            <mesh>
              <scale>1 1 1</scale>
              <uri>/home/cameron/.workspace/src/ez_rassor_description/meshes/drum.dae</uri>
            </mesh>
          </geometry>
          <material>
            <script>
              <name>Gazebo/Orange</name>
              <uri>file://media/materials/scripts/gazebo.material</uri>
            </script>
          </material>
        </visual>
        <gravity>1</gravity>
        <velocity_decay/>
        <self_collide>0</self_collide>
        <kinematic>0</kinematic>
      </link>
      <joint name='drum_back_hinge' type='revolute'>
        <child>drum_back</child>
        <parent>arm_back</parent>
        <axis>
          <xyz>0.000771 1 0</xyz>
          <limit>
            <lower>-1e+16</lower>
            <upper>1e+16</upper>
          </limit>
          <dynamics>
            <spring_reference>0</spring_reference>
            <spring_stiffness>0</spring_stiffness>
          </dynamics>
          <use_parent_model_frame>1</use_parent_model_frame>
        </axis>
      </joint>
      <link name='arm_front'>
        <pose frame=''>0.25 0 0 0 -0 -0.000385</pose>
        <inertial>
          <pose frame=''>0 0 0 0 -0 0</pose>
          <mass>5</mass>
          <inertia>
            <ixx>0.0135417</ixx>
            <ixy>0</ixy>
            <ixz>0</ixz>
            <iyy>0.0135417</iyy>
            <iyz>0</iyz>
            <izz>0.025</izz>
          </inertia>
        </inertial>
        <collision name='arm_front_fixed_joint_lump__collision_collision'>
          <pose frame=''>0 0 0 0 -0 0</pose>
          <geometry>
            <mesh>
              <scale>1 1 1</scale>
              <uri>/home/cameron/.workspace/src/ez_rassor_description/meshes/drum_arm_short.dae</uri>
            </mesh>
          </geometry>
          <max_contacts>10</max_contacts>
          <surface>
            <contact>
              <ode/>
            </contact>
            <bounce/>
            <friction>
              <torsional>
                <ode/>
              </torsional>
              <ode/>
            </friction>
          </surface>
        </collision>
        <visual name='arm_front_fixed_joint_lump__visual_visual'>
          <pose frame=''>0 0 0 0 -0 0</pose>
          <geometry>
            <mesh>
              <scale>1 1 1</scale>
              <uri>/home/cameron/.workspace/src/ez_rassor_description/meshes/drum_arm_short.dae</uri>
            </mesh>
          </geometry>
        </visual>
        <gravity>1</gravity>
        <velocity_decay/>
        <self_collide>0</self_collide>
        <kinematic>0</kinematic>
      </link>
      <joint name='arm_front_hinge' type='revolute'>
        <child>arm_front</child>
        <parent>base_link</parent>
        <axis>
          <xyz>0.000385 1 0</xyz>
          <limit>
            <lower>-1e+16</lower>
            <upper>1e+16</upper>
          </limit>
          <dynamics>
            <spring_reference>0</spring_reference>
            <spring_stiffness>0</spring_stiffness>
          </dynamics>
          <use_parent_model_frame>1</use_parent_model_frame>
        </axis>
      </joint>
      <link name='drum_front'>
        <pose frame=''>0.588245 -0.00013 0 0 -0 -0.000771</pose>
        <inertial>
          <pose frame=''>0 0 0 0 -0 1.5707</pose>
          <mass>5</mass>
          <inertia>
            <ixx>0.0135417</ixx>
            <ixy>0</ixy>
            <ixz>0</ixz>
            <iyy>0.0135417</iyy>
            <iyz>0</iyz>
            <izz>0.025</izz>
          </inertia>
        </inertial>
        <collision name='drum_front_fixed_joint_lump__collision_collision'>
          <pose frame=''>0 0 0 0 -0 1.5707</pose>
          <geometry>
            <mesh>
              <scale>1 1 1</scale>
              <uri>/home/cameron/.workspace/src/ez_rassor_description/meshes/drum.dae</uri>
            </mesh>
          </geometry>
          <max_contacts>10</max_contacts>
          <surface>
            <contact>
              <ode/>
            </contact>
            <bounce/>
            <friction>
              <torsional>
                <ode/>
              </torsional>
              <ode/>
            </friction>
          </surface>
        </collision>
        <visual name='drum_front_visual_visual'>
          <pose frame=''>0 0 0 0 -0 1.5707</pose>
          <geometry>
            <mesh>
              <scale>1 1 1</scale>
              <uri>/home/cameron/.workspace/src/ez_rassor_description/meshes/drum.dae</uri>
            </mesh>
          </geometry>
          <material>
            <script>
              <name>Gazebo/Orange</name>
              <uri>file://media/materials/scripts/gazebo.material</uri>
            </script>
          </material>
        </visual>
        <gravity>1</gravity>
        <velocity_decay/>
        <self_collide>0</self_collide>
        <kinematic>0</kinematic>
      </link>
      <joint name='drum_front_hinge' type='revolute'>
        <child>drum_front</child>
        <parent>arm_front</parent>
        <axis>
          <xyz>0.000771 1 0</xyz>
          <limit>
            <lower>-1e+16</lower>
            <upper>1e+16</upper>
          </limit>
          <dynamics>
            <spring_reference>0</spring_reference>
            <spring_stiffness>0</spring_stiffness>
          </dynamics>
          <use_parent_model_frame>1</use_parent_model_frame>
        </axis>
      </joint>
      <link name='left_wheel_back'>
        <pose frame=''>-0.15 0.15 0 0 -0 0</pose>
        <inertial>
          <pose frame=''>0 0 0 -0 1.5707 1.5707</pose>
          <mass>5</mass>
          <inertia>
            <ixx>0.0135417</ixx>
            <ixy>0</ixy>
            <ixz>0</ixz>
            <iyy>0.0135417</iyy>
            <iyz>0</iyz>
            <izz>0.025</izz>
          </inertia>
        </inertial>
        <collision name='left_wheel_back_fixed_joint_lump__collision_collision'>
          <pose frame=''>0 -0.06 0 3.14159 1.57079 -1.57089</pose>
          <geometry>
            <mesh>
              <scale>1 1 1</scale>
              <uri>/home/cameron/.workspace/src/ez_rassor_description/meshes/wheel.dae</uri>
            </mesh>
          </geometry>
          <max_contacts>10</max_contacts>
          <surface>
            <contact>
              <ode/>
            </contact>
            <bounce/>
            <friction>
              <torsional>
                <ode/>
              </torsional>
              <ode/>
            </friction>
          </surface>
        </collision>
        <visual name='left_wheel_back_visual_visual'>
          <pose frame=''>0 -0.06 0 3.14159 1.57079 -1.57089</pose>
          <geometry>
            <mesh>
              <scale>1 1 1</scale>
              <uri>/home/cameron/.workspace/src/ez_rassor_description/meshes/wheel.dae</uri>
            </mesh>
          </geometry>
        </visual>
        <self_collide>0</self_collide>
        <kinematic>0</kinematic>
        <gravity>1</gravity>
      </link>
      <joint name='left_wheel_back_hinge' type='revolute'>
        <child>left_wheel_back</child>
        <parent>base_link</parent>
        <axis>
          <xyz>0 1 0</xyz>
          <limit>
            <lower>-1e+16</lower>
            <upper>1e+16</upper>
          </limit>
          <dynamics>
            <spring_reference>0</spring_reference>
            <spring_stiffness>0</spring_stiffness>
          </dynamics>
          <use_parent_model_frame>1</use_parent_model_frame>
        </axis>
      </joint>
      <link name='left_wheel_front'>
        <pose frame=''>0.15 0.15 0 0 -0 0</pose>
        <inertial>
          <pose frame=''>0 0 0 -0 1.5707 1.5707</pose>
          <mass>5</mass>
          <inertia>
            <ixx>0.0135417</ixx>
            <ixy>0</ixy>
            <ixz>0</ixz>
            <iyy>0.0135417</iyy>
            <iyz>0</iyz>
            <izz>0.025</izz>
          </inertia>
        </inertial>
        <collision name='left_wheel_front_fixed_joint_lump__collision_collision'>
          <pose frame=''>0 -0.06 0 3.14159 1.57079 -1.57089</pose>
          <geometry>
            <mesh>
              <scale>1 1 1</scale>
              <uri>/home/cameron/.workspace/src/ez_rassor_description/meshes/wheel.dae</uri>
            </mesh>
          </geometry>
          <max_contacts>10</max_contacts>
          <surface>
            <contact>
              <ode/>
            </contact>
            <bounce/>
            <friction>
              <torsional>
                <ode/>
              </torsional>
              <ode/>
            </friction>
          </surface>
        </collision>
        <visual name='left_wheel_front_visual_visual'>
          <pose frame=''>0 -0.06 0 3.14159 1.57079 -1.57089</pose>
          <geometry>
            <mesh>
              <scale>1 1 1</scale>
              <uri>/home/cameron/.workspace/src/ez_rassor_description/meshes/wheel.dae</uri>
            </mesh>
          </geometry>
        </visual>
        <self_collide>0</self_collide>
        <kinematic>0</kinematic>
        <gravity>1</gravity>
      </link>
      <joint name='left_wheel_front_hinge' type='revolute'>
        <child>left_wheel_front</child>
        <parent>base_link</parent>
        <axis>
          <xyz>0 1 0</xyz>
          <limit>
            <lower>-1e+16</lower>
            <upper>1e+16</upper>
          </limit>
          <dynamics>
            <spring_reference>0</spring_reference>
            <spring_stiffness>0</spring_stiffness>
          </dynamics>
          <use_parent_model_frame>1</use_parent_model_frame>
        </axis>
      </joint>
      <link name='right_wheel_back'>
        <pose frame=''>-0.15 -0.15 0 0 -0 0</pose>
        <inertial>
          <pose frame=''>0 0 0 -0 1.5707 1.5707</pose>
          <mass>5</mass>
          <inertia>
            <ixx>0.0135417</ixx>
            <ixy>0</ixy>
            <ixz>0</ixz>
            <iyy>0.0135417</iyy>
            <iyz>0</iyz>
            <izz>0.025</izz>
          </inertia>
        </inertial>
        <collision name='right_wheel_back_fixed_joint_lump__collision_collision'>
          <pose frame=''>0 0.06 0 -3.14159 1.57079 1.5707</pose>
          <geometry>
            <mesh>
              <scale>1 1 1</scale>
              <uri>/home/cameron/.workspace/src/ez_rassor_description/meshes/wheel.dae</uri>
            </mesh>
          </geometry>
          <max_contacts>10</max_contacts>
          <surface>
            <contact>
              <ode/>
            </contact>
            <bounce/>
            <friction>
              <torsional>
                <ode/>
              </torsional>
              <ode/>
            </friction>
          </surface>
        </collision>
        <visual name='right_wheel_back_visual_visual'>
          <pose frame=''>0 0.06 0 -3.14159 1.57079 1.57545</pose>
          <geometry>
            <mesh>
              <scale>1 1 1</scale>
              <uri>/home/cameron/.workspace/src/ez_rassor_description/meshes/wheel.dae</uri>
            </mesh>
          </geometry>
        </visual>
        <self_collide>0</self_collide>
        <kinematic>0</kinematic>
        <gravity>1</gravity>
      </link>
      <joint name='right_wheel_back_hinge' type='revolute'>
        <child>right_wheel_back</child>
        <parent>base_link</parent>
        <axis>
          <xyz>0 1 0</xyz>
          <limit>
            <lower>-1e+16</lower>
            <upper>1e+16</upper>
          </limit>
          <dynamics>
            <spring_reference>0</spring_reference>
            <spring_stiffness>0</spring_stiffness>
          </dynamics>
          <use_parent_model_frame>1</use_parent_model_frame>
        </axis>
      </joint>
      <link name='right_wheel_front'>
        <pose frame=''>0.15 -0.15 0 0 -0 0</pose>
        <inertial>
          <pose frame=''>0 0 0 -0 1.5707 1.5707</pose>
          <mass>5</mass>
          <inertia>
            <ixx>0.0135417</ixx>
            <ixy>0</ixy>
            <ixz>0</ixz>
            <iyy>0.0135417</iyy>
            <iyz>0</iyz>
            <izz>0.025</izz>
          </inertia>
        </inertial>
        <collision name='right_wheel_front_fixed_joint_lump__collision_collision'>
          <pose frame=''>0 0.06 0 -3.14159 1.57079 1.5707</pose>
          <geometry>
            <mesh>
              <scale>1 1 1</scale>
              <uri>/home/cameron/.workspace/src/ez_rassor_description/meshes/wheel.dae</uri>
            </mesh>
          </geometry>
          <max_contacts>10</max_contacts>
          <surface>
            <contact>
              <ode/>
            </contact>
            <bounce/>
            <friction>
              <torsional>
                <ode/>
              </torsional>
              <ode/>
            </friction>
          </surface>
        </collision>
        <visual name='right_wheel_front_visual_visual'>
          <pose frame=''>0 0.06 0 -3.14159 1.57079 1.57545</pose>
          <geometry>
            <mesh>
              <scale>1 1 1</scale>
              <uri>/home/cameron/.workspace/src/ez_rassor_description/meshes/wheel.dae</uri>
            </mesh>
          </geometry>
        </visual>
        <self_collide>0</self_collide>
        <kinematic>0</kinematic>
        <gravity>1</gravity>
      </link>
      <joint name='right_wheel_front_hinge' type='revolute'>
        <child>right_wheel_front</child>
        <parent>base_link</parent>
        <axis>
          <xyz>0 1 0</xyz>
          <limit>
            <lower>-1e+16</lower>
            <upper>1e+16</upper>
          </limit>
          <dynamics>
            <spring_reference>0</spring_reference>
            <spring_stiffness>0</spring_stiffness>
          </dynamics>
          <use_parent_model_frame>1</use_parent_model_frame>
        </axis>
      </joint>
      <static>0</static>
      <plugin name='gazebo_ros_control' filename='libgazebo_ros_control.so'>
        <robotNamespace>/ez_rassor</robotNamespace>
      </plugin>
      <pose frame=''>0 0 0 0 -0 0</pose>
    </model>
    <state world_name='moon'>
      <sim_time>470 620000000</sim_time>
      <real_time>125 911173447</real_time>
      <wall_time>1549132200 662154480</wall_time>
      <iterations>11888</iterations>
      <model name='apollo15_landing_site_1000x1000'>
        <pose frame=''>0 0 0 0 -0 0</pose>
        <scale>1 1 1</scale>
        <link name='link'>
          <pose frame=''>0 0 0 0 -0 0</pose>
          <velocity>0 0 0 0 -0 0</velocity>
          <acceleration>0 0 0 0 -0 0</acceleration>
          <wrench>0 0 0 0 -0 0</wrench>
        </link>
      </model>
      <model name='ez_rassor'>
        <pose frame=''>-0.279508 0.081329 0.414244 -0.096018 -0.137333 -0.007729</pose>
        <scale>1 1 1</scale>
        <link name='arm_back'>
          <pose frame=''>-0.527145 0.083239 0.380021 -0.156423 0.91412 -0.145649</pose>
          <velocity>-3e-05 4e-06 3.1e-05 0.00011 0.006954 -0.000504</velocity>
          <acceleration>8e-06 2.5e-05 -9.1e-05 -0.000306 -0.000914 0.000645</acceleration>
          <wrench>3.8e-05 0.000126 -0.000457 0 -0 0</wrench>
        </link>
        <link name='arm_front'>
          <pose frame=''>-0.031871 0.079427 0.448467 -0.097464 -0.21231 -0.000647</pose>
          <velocity>-3.1e-05 6.5e-05 1.6e-05 -0.000164 9.7e-05 6.7e-05</velocity>
          <acceleration>7e-06 3.7e-05 -0.000112 1.2e-05 -0.000888 0.000206</acceleration>
          <wrench>3.5e-05 0.000185 -0.000559 0 -0 0</wrench>
        </link>
        <link name='base_link'>
          <pose frame=''>-0.279508 0.081329 0.414244 -0.096018 -0.137333 -0.007729</pose>
          <velocity>-3.3e-05 3.6e-05 2.7e-05 -0.000128 2.9e-05 0.000115</velocity>
          <acceleration>2.8e-05 0.000131 -0.000111 -0.000854 0.000101 0.000306</acceleration>
          <wrench>0.000287 0.00135 -0.001145 0 -0 0</wrench>
        </link>
        <link name='drum_back'>
          <pose frame=''>-0.731571 0.113192 0.647898 -0.096307 -0.124944 -0.009579</pose>
          <velocity>0.001782 9.1e-05 0.001444 -0.000359 -0.014688 0.001569</velocity>
          <acceleration>8.2e-05 7e-05 -0.000244 -0.000178 7e-06 0.000268</acceleration>
          <wrench>0.000409 0.000352 -0.001218 0 -0 0</wrench>
        </link>
        <link name='drum_front'>
          <pose frame=''>0.298769 0.079176 0.519752 -1.16802 1.46712 -1.18758</pose>
          <velocity>-4.2e-05 8.8e-05 1e-06 -0.000421 -0.00106 8.3e-05</velocity>
          <acceleration>3.5e-05 -0.000113 6.4e-05 -0.000784 -0.0003 -3.7e-05</acceleration>
          <wrench>0.000175 -0.000563 0.000318 0 -0 0</wrench>
        </link>
        <link name='left_wheel_back'>
          <pose frame=''>-0.424969 0.231751 0.379475 -0.18521 -1.03044 0.138427</pose>
          <velocity>-5.2e-05 1.8e-05 -1e-05 -0.000193 -0.000582 0.000152</velocity>
          <acceleration>4.7e-05 4.4e-05 -0.000204 -0.000639 0.000294 -0.000103</acceleration>
          <wrench>0.000235 0.000221 -0.001021 0 -0 0</wrench>
        </link>
        <link name='left_wheel_front'>
          <pose frame=''>-0.1278 0.229468 0.420517 -0.243676 -1.16452 0.203466</pose>
          <velocity>-5e-05 5.1e-05 -9e-06 -0.000491 -0.000578 5e-05</velocity>
          <acceleration>6.7e-05 1.1e-05 -0.000269 -0.000563 -9.5e-05 -0.00051</acceleration>
          <wrench>0.000336 5.3e-05 -0.001344 0 -0 0</wrench>
        </link>
        <link name='right_wheel_back'>
          <pose frame=''>-0.431205 -0.066837 0.407935 -0.111391 -0.547262 0.0373</pose>
          <velocity>-1e-05 -8e-06 2.5e-05 8.8e-05 6.2e-05 0.000207</velocity>
          <acceleration>1.5e-05 8.8e-05 4.3e-05 -0.000831 0.000158 -0.00013</acceleration>
          <wrench>7.3e-05 0.000438 0.000216 0 -0 0</wrench>
        </link>
        <link name='right_wheel_front'>
          <pose frame=''>-0.134049 -0.069105 0.449031 -0.095625 -0.101938 -0.011148</pose>
          <velocity>-1.7e-05 5.7e-05 4.9e-05 -0.000136 -0.00018 0.000129</velocity>
          <acceleration>3.9e-05 9.4e-05 -1.7e-05 -0.000699 7.5e-05 4.9e-05</acceleration>
          <wrench>0.000196 0.000468 -8.6e-05 0 -0 0</wrench>
        </link>
      </model>
      <model name='unit_box_0'>
        <pose frame=''>-2.19109 0.385585 0.5 0 -0 0</pose>
        <scale>1.89544 4.85091 5.15789</scale>
        <link name='link'>
          <pose frame=''>-2.19109 0.385585 0.5 0 -0 0</pose>
          <velocity>0 0 0 0 -0 0</velocity>
          <acceleration>0 0 0 0 -0 0</acceleration>
          <wrench>0 0 0 0 -0 0</wrench>
        </link>
      </model>
      <model name='unit_box_1'>
        <pose frame=''>-1.29954 0.153657 0.541852 0 -0 0</pose>
        <scale>1 1 1</scale>
        <link name='link'>
          <pose frame=''>-1.29954 0.153657 0.541852 0 -0 0</pose>
          <velocity>0 0 0 0 -0 0</velocity>
          <acceleration>0 0 0 0 -0 0</acceleration>
          <wrench>0 0 0 0 -0 0</wrench>
        </link>
      </model>
      <light name='sun'>
        <pose frame=''>0 0 10 0 -0 0</pose>
      </light>
    </state>
    <gui fullscreen='0'>
      <camera name='user_camera'>
        <pose frame=''>-0.104596 4.61158 0.586803 0 0.039456 -1.73099</pose>
        <view_controller>orbit</view_controller>
        <projection_type>perspective</projection_type>
      </camera>
    </gui>
    <model name='unit_box_0'>
      <pose frame=''>-1.64923 0.186529 0.5 0 -0 0</pose>
      <link name='link'>
        <inertial>
          <mass>1</mass>
          <inertia>
            <ixx>0.166667</ixx>
            <ixy>0</ixy>
            <ixz>0</ixz>
            <iyy>0.166667</iyy>
            <iyz>0</iyz>
            <izz>0.166667</izz>
          </inertia>
        </inertial>
        <collision name='collision'>
          <geometry>
            <box>
              <size>1 1 0.999999</size>
            </box>
          </geometry>
          <max_contacts>10</max_contacts>
          <surface>
            <contact>
              <ode/>
            </contact>
            <bounce/>
            <friction>
              <torsional>
                <ode/>
              </torsional>
              <ode/>
            </friction>
          </surface>
        </collision>
        <visual name='visual'>
          <geometry>
            <box>
              <size>1 1 0.999999</size>
            </box>
          </geometry>
          <material>
            <script>
              <name>Gazebo/Grey</name>
              <uri>file://media/materials/scripts/gazebo.material</uri>
            </script>
          </material>
        </visual>
        <self_collide>0</self_collide>
        <kinematic>0</kinematic>
        <gravity>1</gravity>
      </link>
    </model>
    <model name='unit_box_1'>
      <pose frame=''>-0.967772 0.064674 0.5 0 -0 0</pose>
      <link name='link'>
        <inertial>
          <mass>1</mass>
          <inertia>
            <ixx>0.166667</ixx>
            <ixy>0</ixy>
            <ixz>0</ixz>
            <iyy>0.166667</iyy>
            <iyz>0</iyz>
            <izz>0.166667</izz>
          </inertia>
        </inertial>
        <collision name='collision'>
          <geometry>
            <box>
              <size>1 1 1</size>
            </box>
          </geometry>
          <max_contacts>10</max_contacts>
          <surface>
            <contact>
              <ode/>
            </contact>
            <bounce/>
            <friction>
              <torsional>
                <ode/>
              </torsional>
              <ode/>
            </friction>
          </surface>
        </collision>
        <visual name='visual'>
          <geometry>
            <box>
              <size>1 1 1</size>
            </box>
          </geometry>
          <material>
            <script>
              <name>Gazebo/Grey</name>
              <uri>file://media/materials/scripts/gazebo.material</uri>
            </script>
          </material>
        </visual>
        <self_collide>0</self_collide>
        <kinematic>0</kinematic>
        <gravity>1</gravity>
      </link>
    </model>
  </world>
</sdf>
